<?xml version="1.0" ?>
<!-- =================================================================================== -->
<!-- |    This document was autogenerated by xacro from dingo.urdf.xacro               | -->
<!-- |    EDITING THIS FILE BY HAND IS NOT RECOMMENDED                                 | -->
<!-- =================================================================================== -->
<!-- Link Name,Center of Mass X,Center of Mass Y,Center of Mass Z,Center of Mass Roll,Center of Mass Pitch,Center of Mass Yaw,Mass,Moment Ixx,Moment Ixy,Moment Ixz,Moment Iyy,Moment Iyz,Moment Izz,Visual X,Visual Y,Visual Z,Visual Roll,Visual Pitch,Visual Yaw,Mesh Filename,Color Red,Color Green,Color Blue,Color Alpha,Collision X,Collision Y,Collision Z,Collision Roll,Collision Pitch,Collision Yaw,Collision Mesh Filename,Material Name,SW Components,Coordinate System,Axis Name,Joint Name,Joint Type,Joint Origin X,Joint Origin Y,Joint Origin Z,Joint Origin Roll,Joint Origin Pitch,Joint Origin Yaw,Parent,Joint Axis X,Joint Axis Y,Joint Axis Z,Limit Effort,Limit Velocity,Limit Lower,Limit Upper,Calibration rising,Calibration falling,Dynamics Damping,Dynamics Friction,Safety Soft Upper,Safety Soft Lower,Safety K Position,Safety K Velocity
base_link,0.0014631,-0.00014888,-0.00304,0,0,0,2.2,0.0013473,-5.7062E-07,-3.8658E-06,0.0024951,4.4539E-07,0.0032361,0,0,0,0,0,0,package://dingo_description/meshes/base_link.STL,0.79216,0.81961,0.93333,1,0,0,0,0,0,0,package://dingo_description/meshes/base_link.STL,,Link0-1,Origin_global,,,,0,0,0,0,0,0,,0,0,0,,,,,,,,,,,,
FL_link1,0.0099246,0.0072705,0.0095717,0,0,0,0.2,3.5552E-05,4.3357E-08,2.126E-08,3.3482E-05,-1.3221E-07,1.9902E-05,0,0,0,0,0,0,package://dingo_description/meshes/FL_link1.STL,0.79216,0.81961,0.93333,1,0,0,0,0,0,0,package://dingo_description/meshes/FL_link1.STL,,Link1_FrontLeft-1,Origin_FL_theta1,Axis_FL_theta1,FL_theta1,continuous,0.11165,0.061,-0.0144,1.5708,0,1.5708,base_link,0,0,1,,,,,,,,,,,,
FL_link2,0.04716,-9.1E-06,0.0027797,0,0,0,0.05,2.7283E-06,-6.5997E-10,1.8046E-06,7.2343E-05,-2.0176E-09,7.3964E-05,0,0,0,0,0,0,package://dingo_description/meshes/FL_link2.STL,0.79216,0.81961,0.93333,1,0,0,0,0,0,0,package://dingo_description/meshes/FL_link2.STL,,Link2_Left-2,Origin_FL_theta2,Axis_FL_theta2,FL_theta2,continuous,0.0496000007984339,0.014400000013256,0,1.57079634307336,1.57079568414183,-1.57079631051644,FL_link1,0,0,1,,,,,,,,,,,,
FL_link3,0.050883,0.0040212,0.00066702,0,0,0,0.05,4.9316E-06,-7.1103E-06,2.5244E-06,8.9179E-05,2.3247E-07,8.8368E-05,0,0,0,0,0,0,package://dingo_description/meshes/FL_link3.STL,0.79216,0.81961,0.93333,1,0,0,0,0,0,0,package://dingo_description/meshes/FL_link3.STL,,Link3_left-2,Origin_FL_theta3,Axis_FL_theta3,FL_theta3,continuous,0.129999999999897,0,0,0,0,1.57079594774422,FL_link2,0,0,1,,,,,,,,,,,,
FL_link4,-0.0035222,0.0032708,7.8202E-12,0,0,0,0.01,4.34E-08,-1.0272E-08,-3.4038E-16,4.1878E-08,3.1906E-16,3.2338E-08,0,0,0,0,0,0,package://dingo_description/meshes/FL_link4.STL,0.79216,0.81961,0.93333,1,0,0,0,0,0,0,package://dingo_description/meshes/FL_link4.STL,,Link4-2,Origin_FL_foot,Axis_FL_foot,FL_foot,fixed,0.138136646352288,0,0,0,0,0,FL_link3,0,0,0,,,,,,,,,,,,
FR_link1,-0.0099246,0.0072016,0.009573,0,0,0,0.2,3.5552E-05,4.3356E-08,-2.0644E-08,3.3482E-05,-1.3216E-07,1.9902E-05,0,0,0,0,0,0,package://dingo_description/meshes/FR_link1.STL,0.79216,0.81961,0.93333,1,0,0,0,0,0,0,package://dingo_description/meshes/FR_link1.STL,,Link1_FrontRight-1,Origin_FR_theta1,Axis_FR_theta1,FR_theta1,continuous,0.111650000000002,-0.0609999999999988,-0.0144000000000242,1.57079632679492,0,1.5707963267949,base_link,0,0,-1,,,,,,,,,,,,
FR_link2,0.047105,-3.823E-07,-0.0027801,0,0,0,0.05,2.7284E-06,-2.0045E-09,-1.7926E-06,7.2365E-05,8.4078E-11,7.3986E-05,0,0,0,0,0,0,package://dingo_description/meshes/FR_link2.STL,0.79216,0.81961,0.93333,1,0,0,0,0,0,0,package://dingo_description/meshes/FR_link2.STL,,Link2_Right-2,Origin_FR_theta2,Axis_FR_theta2,FR_theta2,continuous,-0.0495999992169121,0.0144000000000242,0,1.57079632309575,1.57079572077363,-1.57079633049404,FR_link1,0,0,1,,,,,,,,,,,,
FR_link3,0.050883,0.0040212,-0.00066701,0,0,0,0.05,4.9316E-06,-7.1103E-06,-2.5245E-06,8.9179E-05,-2.3248E-07,8.8368E-05,0,0,0,0,0,0,package://dingo_description/meshes/FR_link3.STL,0.79216,0.81961,0.93333,1,0,0,0,0,0,0,package://dingo_description/meshes/FR_link3.STL,,Link3_Right-2,Origin_FR_theta3,Axis_FR_theta3,FR_theta3,continuous,0.13000000353672,0,0,0,0,1.57079598438978,FR_link2,0,0,1,,,,,,,,,,,,
FR_link4,-0.0035222,0.0032708,6.3288E-11,0,0,0,0.01,4.34E-08,-1.0272E-08,-5.1458E-16,4.1878E-08,4.8083E-16,3.2338E-08,0,0,0,0,0,0,package://dingo_description/meshes/FR_link4.STL,0.79216,0.81961,0.93333,1,0,0,0,0,0,0,package://dingo_description/meshes/FR_link4.STL,,Link4-4,Origin_FR_foot,Axis_FR_foot,FR_foot,fixed,0.13813664635243,0,0,0,0,0,FR_link3,0,0,0,,,,,,,,,,,,
RL_link1,0.0099246,0.0072017,0.010375,0,0,0,0.2,3.5552E-05,-4.3357E-08,2.0644E-08,3.3482E-05,-1.3221E-07,1.9902E-05,0,0,0,0,0,0,package://dingo_description/meshes/RL_link1.STL,0.79216,0.81961,0.93333,1,0,0,0,0,0,0,package://dingo_description/meshes/RL_link1.STL,,Link1_Rearleft-1,Origin_RL_theta1,Axis_RL_theta1,RL_theta1,continuous,-0.11165,0.061,-0.0144,1.5708,0,1.5708,base_link,0,0,1,,,,,,,,,,,,
RL_link2,0.04716,-9.1001E-06,0.0027797,0,0,0,0.05,2.7283E-06,-6.5997E-10,1.8046E-06,7.2343E-05,-2.0176E-09,7.3964E-05,0,0,0,0,0,0,package://dingo_description/meshes/RL_link2.STL,0.79216,0.81961,0.93333,1,0,0,0,0,0,0,package://dingo_description/meshes/RL_link2.STL,,Link2_Left-1,Origin_RL_theta2,Axis_RL_theta2,RL_theta2,continuous,0.0496000007984574,0.014399999996394,0,1.5707963301177,1.57079568414183,-1.57079632347209,RL_link1,0,0,1,,,,,,,,,,,,
RL_link3,0.050883,0.0040212,0.00066703,0,0,0,0.05,4.9316E-06,-7.1103E-06,2.5244E-06,8.9179E-05,2.3247E-07,8.8368E-05,0,0,0,0,0,0,package://dingo_description/meshes/RL_link3.STL,0.79216,0.81961,0.93333,1,0,0,0,0,0,0,package://dingo_description/meshes/RL_link3.STL,,Link3_left-1,Origin_RL_theta3,Axis_RL_theta3,RL_theta3,continuous,0.129999999994849,0,0,0,0,1.57079594787326,RL_link2,0,0,0.999999999999979,,,,,,,,,,,,
RL_link4,-0.0035222,0.0032708,6.3535E-10,0,0,0,0.01,4.34E-08,-1.0272E-08,-2.3143E-15,4.1878E-08,2.1487E-15,3.2338E-08,0,0,0,0,0,0,package://dingo_description/meshes/RL_link4.STL,0.79216,0.81961,0.93333,1,0,0,0,0,0,0,package://dingo_description/meshes/RL_link4.STL,,Link4-1,Origin_RL_foot,Axis_RL_foot,RL_foot,fixed,0.138136646352323,0,0,0,0,0,RL_link3,0,0,0,,,,,,,,,,,,
RR_link1,0.0014631,-0.00014888,-0.00304,0,0,0,0.2,0.0013473,-5.7062E-07,-3.8658E-06,0.0024951,4.4539E-07,0.0032361,0,0,0,0,0,0,package://dingo_description/meshes/RR_link1.STL,0.79216,0.81961,0.93333,1,0,0,0,0,0,0,package://dingo_description/meshes/RR_link1.STL,,Link1_RearRight-1,Origin_RR_theta1,Axis_RR_theta1,RR_theta1,continuous,-0.111650000000003,-0.0609999999999995,-0.0144000000000178,1.57079632679492,0,1.5707963267949,base_link,0,0,-1,,,,,,,,,,,,
RR_link2,0.047105,-3.823E-07,-0.0027801,0,0,0,0.05,2.7284E-06,-2.0045E-09,-1.7926E-06,7.2365E-05,8.4078E-11,7.3986E-05,0,0,0,0,0,0,package://dingo_description/meshes/RR_link2.STL,0.79216,0.81961,0.93333,1,0,0,0,0,0,0,package://dingo_description/meshes/RR_link2.STL,,Link2_Right-1,Origin_RR_theta2,Axis_RR_theta2,RR_theta2,continuous,-0.0495999992169147,0.0144000000000178,0,1.57079631992506,1.57079572077363,-1.57079633366473,RR_link1,0,0,1,,,,,,,,,,,,
RR_link3,0.050883,0.0040212,-0.00066701,0,0,0,0.05,4.9316E-06,-7.1103E-06,-2.5245E-06,8.9179E-05,-2.3248E-07,8.8368E-05,0,0,0,0,0,0,package://dingo_description/meshes/RR_link3.STL,0.79216,0.81961,0.93333,1,0,0,0,0,0,0,package://dingo_description/meshes/RR_link3.STL,,Link3_Right-1,Origin_RR_theta3,Axis_RR_theta3,RR_theta3,continuous,0.13000000353672,0,0,0,0,1.57079598438978,RR_link2,0,0,0.999999999999998,,,,,,,,,,,,
RR_link4,-0.0035222,0.0032708,7.8203E-12,0,0,0,0.01,4.34E-08,-1.0272E-08,-3.4038E-16,4.1878E-08,3.1906E-16,3.2338E-08,0,0,0,0,0,0,package://dingo_description/meshes/RR_link4.STL,0.79216,0.81961,0.93333,1,0,0,0,0,0,0,package://dingo_description/meshes/RR_link4.STL,,Link4-3,Origin_RR_foot,Axis_RR_foot,RR_foot,fixed,0.138136646352431,0,0,0,0,0,RR_link3,0,0,0,,,,,,,,,,,, -->
<robot name="dingo">
  <!-- The root link can't have inertia so did this -->
  <link name="world_link"/>
  <!-- Fixed joint connecting dummy link to base_link -->
  <joint name="world_to_base" type="fixed">
    <parent link="world_link"/>
    <child link="base_link"/>
  </joint>
  <!-- The root link can't have inertia so did this -->
  <!-- base_link -->
  <link name="base_link">
    <inertial>
      <origin rpy="0 0 0" xyz="0.0014631 -0.00014888 -0.00304"/>
      <mass value="2.2"/>
      <inertia ixx="0.0013473" ixy="-5.7062E-07" ixz="-3.8658E-06" iyy="0.0024951" iyz="4.4539E-07" izz="0.0032361"/>
    </inertial>
    <visual>
      <origin rpy="0 0 0" xyz="0 0 0"/>
      <geometry>
        <mesh filename="package://magbot_gazebo/description/meshes/base_link.dae"/>
      </geometry>
      <material name="">
        <color rgba="0.15294 0.78431 0.96078 1"/>
      </material>
    </visual>
    <collision>
      <origin rpy="0 0 0" xyz="0 0 0"/>
      <geometry>
        <mesh filename="package://magbot_gazebo/description/meshes/base_collision.STL"/>
      </geometry>
    </collision>
  </link>
  <!-- FL_link1 -->
  <link name="FL_link1">
    <inertial>
      <origin rpy="0 0 0" xyz="0.0099246 0.0072705 0.0095717"/>
      <mass value="0.2"/>
      <inertia ixx="3.5552E-05" ixy="4.3357E-08" ixz="2.126E-08" iyy="3.3482E-05" iyz="-1.3221E-07" izz="1.9902E-05"/>
    </inertial>
    <visual>
      <origin rpy="0 0 0" xyz="0 0 0"/>
      <geometry>
        <mesh filename="package://magbot_gazebo/description/meshes/FL_link1.dae"/>
      </geometry>
      <material name="">
        <color rgba="0.15294 0.78431 0.96078 1"/>
      </material>
    </visual>
    <collision>
      <origin rpy="0 0 0" xyz="0 0 0"/>
      <geometry>
        <mesh filename="package://magbot_gazebo/description/meshes/L_link1_collision.STL"/>
      </geometry>
    </collision>
  </link>
  <!-- FL_link2 -->
  <link name="FL_link2">
    <inertial>
      <origin rpy="0 0 0" xyz="0.04716 -9.1E-06 0.0027797"/>
      <mass value="0.05"/>
      <inertia ixx="2.7283E-06" ixy="-6.5997E-10" ixz="1.8046E-06" iyy="7.2343E-05" iyz="-2.0176E-09" izz="7.3964E-05"/>
    </inertial>
    <visual>
      <origin rpy="0 0 0" xyz="0 0 0"/>
      <geometry>
        <mesh filename="package://magbot_gazebo/description/meshes/L_link2.dae"/>
      </geometry>
      <material name="">
        <color rgba="0.15294 0.78431 0.96078 1"/>
      </material>
    </visual>
    <collision>
      <origin rpy="0 0 0" xyz="0 0 0"/>
      <geometry>
        <mesh filename="package://magbot_gazebo/description/meshes/L_link2_collision.STL"/>
      </geometry>
    </collision>
  </link>
  <!-- FL_link3 -->
  <link name="FL_link3">
    <inertial>
      <origin rpy="0 0 0" xyz="0.050883 0.0040212 0.00066702"/>
      <mass value="0.05"/>
      <inertia ixx="4.9316E-06" ixy="-7.1103E-06" ixz="2.5244E-06" iyy="8.9179E-05" iyz="2.3247E-07" izz="8.8368E-05"/>
    </inertial>
    <visual>
      <origin rpy="0 0 0" xyz="0 0 0"/>
      <geometry>
        <mesh filename="package://magbot_gazebo/description/meshes/L_link3.dae"/>
      </geometry>
      <material name="">
        <color rgba="0.15294 0.78431 0.96078 1"/>
      </material>
    </visual>
    <collision>
      <origin rpy="0 0 0" xyz="0 0 0"/>
      <geometry>
        <mesh filename="package://magbot_gazebo/description/meshes/L_link3_collision.STL"/>
      </geometry>
    </collision>
  </link>
  <!-- FL_link4 -->
  <link name="FL_link4">
    <inertial>
      <origin rpy="0 0 0" xyz="-0.0035222 0.0032708 7.8202E-12"/>
      <mass value="0.01"/>
      <inertia ixx="4.34E-08" ixy="-1.0272E-08" ixz="-3.4038E-16" iyy="4.1878E-08" iyz="3.1906E-16" izz="3.2338E-08"/>
    </inertial>
    <visual>
      <origin rpy="0 0 0" xyz="0 0 0"/>
      <geometry>
        <mesh filename="package://magbot_gazebo/description/meshes/link4.dae"/>
      </geometry>
      <material name="">
        <color rgba="0.15294 0.78431 0.96078 1"/>
      </material>
    </visual>
    <collision>
      <origin rpy="0 0 0" xyz="0 0 0"/>
      <geometry>
        <mesh filename="package://magbot_gazebo/description/meshes/link4_collision.STL"/>
      </geometry>
    </collision>
  </link>
  <!-- FR_link1 -->
  <link name="FR_link1">
    <inertial>
      <origin rpy="0 0 0" xyz="-0.0099246 0.0072016 0.009573"/>
      <mass value="0.2"/>
      <inertia ixx="3.5552E-05" ixy="4.3356E-08" ixz="-2.0644E-08" iyy="3.3482E-05" iyz="-1.3216E-07" izz="1.9902E-05"/>
    </inertial>
    <visual>
      <origin rpy="0 0 0" xyz="0 0 0"/>
      <geometry>
        <mesh filename="package://magbot_gazebo/description/meshes/FR_link1.dae"/>
      </geometry>
      <material name="">
        <color rgba="0.15294 0.78431 0.96078 1"/>
      </material>
    </visual>
    <collision>
      <origin rpy="0 0 0" xyz="0 0 0"/>
      <geometry>
        <mesh filename="package://magbot_gazebo/description/meshes/R_link1_collision.STL"/>
      </geometry>
    </collision>
  </link>
  <!-- FR_link2 -->
  <link name="FR_link2">
    <inertial>
      <origin rpy="0 0 0" xyz="0.047105 -3.823E-07 -0.0027801"/>
      <mass value="0.05"/>
      <inertia ixx="2.7284E-06" ixy="-2.0045E-09" ixz="-1.7926E-06" iyy="7.2365E-05" iyz="8.4078E-11" izz="7.3986E-05"/>
    </inertial>
    <visual>
      <origin rpy="0 0 0" xyz="0 0 0"/>
      <geometry>
        <mesh filename="package://magbot_gazebo/description/meshes/R_link2.dae"/>
      </geometry>
      <material name="">
        <color rgba="0.15294 0.78431 0.96078 1"/>
      </material>
    </visual>
    <collision>
      <origin rpy="0 0 0" xyz="0 0 0"/>
      <geometry>
        <mesh filename="package://magbot_gazebo/description/meshes/R_link2_collision.STL"/>
      </geometry>
    </collision>
  </link>
  <!-- FR_link3 -->
  <link name="FR_link3">
    <inertial>
      <origin rpy="0 0 0" xyz="0.050883 0.0040212 -0.00066701"/>
      <mass value="0.05"/>
      <inertia ixx="4.9316E-06" ixy="-7.1103E-06" ixz="-2.5245E-06" iyy="8.9179E-05" iyz="-2.3248E-07" izz="8.8368E-05"/>
    </inertial>
    <visual>
      <origin rpy="0 0 0" xyz="0 0 0"/>
      <geometry>
        <mesh filename="package://magbot_gazebo/description/meshes/R_link3.dae"/>
      </geometry>
      <material name="">
        <color rgba="0.15294 0.78431 0.96078 1"/>
      </material>
    </visual>
    <collision>
      <origin rpy="0 0 0" xyz="0 0 0"/>
      <geometry>
        <mesh filename="package://magbot_gazebo/description/meshes/R_link3_collision.STL"/>
      </geometry>
    </collision>
  </link>
  <!-- FR_link4 -->
  <link name="FR_link4">
    <inertial>
      <origin rpy="0 0 0" xyz="-0.0035222 0.0032708 6.3288E-11"/>
      <mass value="0.01"/>
      <inertia ixx="4.34E-08" ixy="-1.0272E-08" ixz="-5.1458E-16" iyy="4.1878E-08" iyz="4.8083E-16" izz="3.2338E-08"/>
    </inertial>
    <visual>
      <origin rpy="0 0 0" xyz="0 0 0"/>
      <geometry>
        <mesh filename="package://magbot_gazebo/description/meshes/link4.dae"/>
      </geometry>
      <material name="">
        <color rgba="0.15294 0.78431 0.96078 1"/>
      </material>
    </visual>
    <collision>
      <origin rpy="0 0 0" xyz="0 0 0"/>
      <geometry>
        <mesh filename="package://magbot_gazebo/description/meshes/link4_collision.STL"/>
      </geometry>
    </collision>
  </link>
  <!-- RL_link1 -->
  <link name="RL_link1">
    <inertial>
      <origin rpy="0 0 0" xyz="0.0099246 0.0072017 0.010375"/>
      <mass value="0.2"/>
      <inertia ixx="3.5552E-05" ixy="-4.3357E-08" ixz="2.0644E-08" iyy="3.3482E-05" iyz="-1.3221E-07" izz="1.9902E-05"/>
    </inertial>
    <visual>
      <origin rpy="0 0 0" xyz="0 0 0"/>
      <geometry>
        <mesh filename="package://magbot_gazebo/description/meshes/RL_link1.dae"/>
      </geometry>
      <material name="">
        <color rgba="0.15294 0.78431 0.96078 1"/>
      </material>
    </visual>
    <collision>
      <origin rpy="0 0 0" xyz="0 0 0"/>
      <geometry>
        <mesh filename="package://magbot_gazebo/description/meshes/L_link1_collision.STL"/>
      </geometry>
    </collision>
  </link>
  <!-- RL_link2 -->
  <link name="RL_link2">
    <inertial>
      <origin rpy="0 0 0" xyz="0.04716 -9.1001E-06 0.0027797"/>
      <mass value="0.05"/>
      <inertia ixx="2.7283E-06" ixy="-6.5997E-10" ixz="1.8046E-06" iyy="7.2343E-05" iyz="-2.0176E-09" izz="7.3964E-05"/>
    </inertial>
    <visual>
      <origin rpy="0 0 0" xyz="0 0 0"/>
      <geometry>
        <mesh filename="package://magbot_gazebo/description/meshes/L_link2.dae"/>
      </geometry>
      <material name="">
        <color rgba="0.15294 0.78431 0.96078 1"/>
      </material>
    </visual>
    <collision>
      <origin rpy="0 0 0" xyz="0 0 0"/>
      <geometry>
        <mesh filename="package://magbot_gazebo/description/meshes/L_link2_collision.STL"/>
      </geometry>
    </collision>
  </link>
  <!-- RL_link3 -->
  <link name="RL_link3">
    <inertial>
      <origin rpy="0 0 0" xyz="0.050883 0.0040212 0.00066703"/>
      <mass value="0.05"/>
      <inertia ixx="4.9316E-06" ixy="-7.1103E-06" ixz="2.5244E-06" iyy="8.9179E-05" iyz="2.3247E-07" izz="8.8368E-05"/>
    </inertial>
    <visual>
      <origin rpy="0 0 0" xyz="0 0 0"/>
      <geometry>
        <mesh filename="package://magbot_gazebo/description/meshes/L_link3.dae"/>
      </geometry>
      <material name="">
        <color rgba="0.15294 0.78431 0.96078 1"/>
      </material>
    </visual>
    <collision>
      <origin rpy="0 0 0" xyz="0 0 0"/>
      <geometry>
        <mesh filename="package://magbot_gazebo/description/meshes/L_link3_collision.STL"/>
      </geometry>
    </collision>
  </link>
  <!-- RL_link4 -->
  <link name="RL_link4">
    <inertial>
      <origin rpy="0 0 0" xyz="-0.0035222 0.0032708 6.3535E-10"/>
      <mass value="0.01"/>
      <inertia ixx="4.34E-08" ixy="-1.0272E-08" ixz="-2.3143E-15" iyy="4.1878E-08" iyz="2.1487E-15" izz="3.2338E-08"/>
    </inertial>
    <visual>
      <origin rpy="0 0 0" xyz="0 0 0"/>
      <geometry>
        <mesh filename="package://magbot_gazebo/description/meshes/link4.dae"/>
      </geometry>
      <material name="">
        <color rgba="0.15294 0.78431 0.96078 1"/>
      </material>
    </visual>
    <collision>
      <origin rpy="0 0 0" xyz="0 0 0"/>
      <geometry>
        <mesh filename="package://magbot_gazebo/description/meshes/link4_collision.STL"/>
      </geometry>
    </collision>
  </link>
  <!-- RR_link1 -->
  <link name="RR_link1">
    <inertial>
      <origin rpy="0 0 0" xyz="0.0014631 -0.00014888 -0.00304"/>
      <mass value="0.2"/>
      <inertia ixx="0.0013473" ixy="-5.7062E-07" ixz="-3.8658E-06" iyy="0.0024951" iyz="4.4539E-07" izz="0.0032361"/>
    </inertial>
    <visual>
      <origin rpy="0 0 0" xyz="0 0 0"/>
      <geometry>
        <mesh filename="package://magbot_gazebo/description/meshes/RR_link1.dae"/>
      </geometry>
      <material name="">
        <color rgba="0.15294 0.78431 0.96078 1"/>
      </material>
    </visual>
    <collision>
      <origin rpy="0 0 0" xyz="0 0 0"/>
      <geometry>
        <mesh filename="package://magbot_gazebo/description/meshes/R_link1_collision.STL"/>
      </geometry>
    </collision>
  </link>
  <!-- RR_link2 -->
  <link name="RR_link2">
    <inertial>
      <origin rpy="0 0 0" xyz="0.047105 -3.823E-07 -0.0027801"/>
      <mass value="0.05"/>
      <inertia ixx="2.7284E-06" ixy="-2.0045E-09" ixz="-1.7926E-06" iyy="7.2365E-05" iyz="8.4078E-11" izz="7.3986E-05"/>
    </inertial>
    <visual>
      <origin rpy="0 0 0" xyz="0 0 0"/>
      <geometry>
        <mesh filename="package://magbot_gazebo/description/meshes/R_link2.dae"/>
      </geometry>
      <material name="">
        <color rgba="0.15294 0.78431 0.96078 1"/>
      </material>
    </visual>
    <collision>
      <origin rpy="0 0 0" xyz="0 0 0"/>
      <geometry>
        <mesh filename="package://magbot_gazebo/description/meshes/R_link2_collision.STL"/>
      </geometry>
    </collision>
  </link>
  <!-- RR_link3 -->
  <link name="RR_link3">
    <inertial>
      <origin rpy="0 0 0" xyz="0.050883 0.0040212 -0.00066701"/>
      <mass value="0.05"/>
      <inertia ixx="4.9316E-06" ixy="-7.1103E-06" ixz="-2.5245E-06" iyy="8.9179E-05" iyz="-2.3248E-07" izz="8.8368E-05"/>
    </inertial>
    <visual>
      <origin rpy="0 0 0" xyz="0 0 0"/>
      <geometry>
        <mesh filename="package://magbot_gazebo/description/meshes/R_link3.dae"/>
      </geometry>
      <material name="">
        <color rgba="0.15294 0.78431 0.96078 1"/>
      </material>
    </visual>
    <collision>
      <origin rpy="0 0 0" xyz="0 0 0"/>
      <geometry>
        <mesh filename="package://magbot_gazebo/description/meshes/R_link3_collision.STL"/>
      </geometry>
    </collision>
  </link>
  <!-- RR_link4 -->
  <link name="RR_link4">
    <inertial>
      <origin rpy="0 0 0" xyz="-0.0035222 0.0032708 7.8203E-12"/>
      <mass value="0.01"/>
      <inertia ixx="4.34E-08" ixy="-1.0272E-08" ixz="-3.4038E-16" iyy="4.1878E-08" iyz="3.1906E-16" izz="3.2338E-08"/>
    </inertial>
    <visual>
      <origin rpy="0 0 0" xyz="0 0 0"/>
      <geometry>
        <mesh filename="package://magbot_gazebo/description/meshes/link4.dae"/>
      </geometry>
      <material name="">
        <color rgba="0.15294 0.78431 0.96078 1"/>
      </material>
    </visual>
    <collision>
      <origin rpy="0 0 0" xyz="0 0 0"/>
      <geometry>
        <mesh filename="package://magbot_gazebo/description/meshes/link4_collision.STL"/>
      </geometry>
    </collision>
  </link>
  <!-- JOINTS -->
  <joint name="FL_theta1" type="revolute">
    <origin rpy="1.5708 0 1.5708" xyz="0.11165 0.061 -0.0144"/>
    <parent link="base_link"/>
    <child link="FL_link1"/>
    <axis xyz="0 0 1"/>
    <limit effort="10" lower="-0.785398" upper="0.785398" velocity="3"/>
    <dynamics damping="1000.0" friction="1000.0"/>
  </joint>
  <joint name="FL_theta2" type="revolute">
    <origin rpy="1.57079634307336 1.57079568414183 -1.57079631051644" xyz="0.0496000007984339 0.014400000013256 0"/>
    <parent link="FL_link1"/>
    <child link="FL_link2"/>
    <axis xyz="0 0 1"/>
    <limit effort="10" lower="-3" upper="3" velocity="3"/>
    <dynamics damping="1000.0" friction="1000.0"/>
  </joint>
  <joint name="FL_theta3" type="revolute">
    <origin rpy="0 0 1.57079594774422" xyz="0.129999999999897 0 0"/>
    <parent link="FL_link2"/>
    <child link="FL_link3"/>
    <axis xyz="0 0 1"/>
    <limit effort="10" lower="-3" upper="3" velocity="3"/>
    <dynamics damping="1000.0" friction="1000.0"/>
  </joint>
  <joint name="FL_foot" type="fixed">
    <origin rpy="0 0 0" xyz="0.138136646352288 0 0"/>
    <parent link="FL_link3"/>
    <child link="FL_link4"/>
    <axis xyz="0 0 0"/>
  </joint>
  <joint name="FR_theta1" type="revolute">
    <origin rpy="1.57079632679492 0 1.5707963267949" xyz="0.111650000000002 -0.0609999999999988 -0.0144000000000242"/>
    <parent link="base_link"/>
    <child link="FR_link1"/>
    <axis xyz="0 0 -1"/>
    <limit effort="10" lower="-0.785398" upper="0.785398" velocity="3"/>
    <dynamics damping="1000.0" friction="1000.0"/>
  </joint>
  <joint name="FR_theta2" type="revolute">
    <origin rpy="1.57079632309575 1.57079572077363 -1.57079633049404" xyz="-0.0495999992169121 0.0144000000000242 0"/>
    <parent link="FR_link1"/>
    <child link="FR_link2"/>
    <axis xyz="0 0 1"/>
    <limit effort="10" lower="-3" upper="3" velocity="3"/>
    <dynamics damping="1000.0" friction="1000.0"/>
  </joint>
  <joint name="FR_theta3" type="revolute">
    <origin rpy="0 0 1.57079598438978" xyz="0.13000000353672 0 0"/>
    <parent link="FR_link2"/>
    <child link="FR_link3"/>
    <axis xyz="0 0 1"/>
    <limit effort="10" lower="-3" upper="3" velocity="3"/>
    <dynamics damping="1000.0" friction="1000.0"/>
  </joint>
  <joint name="FR_foot" type="fixed">
    <origin rpy="0 0 0" xyz="0.13813664635243 0 0"/>
    <parent link="FR_link3"/>
    <child link="FR_link4"/>
    <axis xyz="0 0 0"/>
  </joint>
  <joint name="RL_theta1" type="revolute">
    <origin rpy="1.5708 0 1.5708" xyz="-0.11165 0.061 -0.0144"/>
    <parent link="base_link"/>
    <child link="RL_link1"/>
    <axis xyz="0 0 1"/>
    <limit effort="10" lower="-0.785398" upper="0.785398" velocity="3"/>
    <dynamics damping="1000.0" friction="1000.0"/>
  </joint>
  <joint name="RL_theta2" type="revolute">
    <origin rpy="1.5707963301177 1.57079568414183 -1.57079632347209" xyz="0.0496000007984574 0.014399999996394 0"/>
    <parent link="RL_link1"/>
    <child link="RL_link2"/>
    <axis xyz="0 0 1"/>
    <limit effort="10" lower="-3" upper="3" velocity="3"/>
    <dynamics damping="1000.0" friction="1000.0"/>
  </joint>
  <joint name="RL_theta3" type="revolute">
    <origin rpy="0 0 1.57079594787326" xyz="0.129999999994849 0 0"/>
    <parent link="RL_link2"/>
    <child link="RL_link3"/>
    <axis xyz="0 0 0.999999999999979"/>
    <limit effort="10" lower="-3" upper="3" velocity="3"/>
    <dynamics damping="1000.0" friction="1000.0"/>
  </joint>
  <joint name="RL_foot" type="fixed">
    <origin rpy="0 0 0" xyz="0.138136646352323 0 0"/>
    <parent link="RL_link3"/>
    <child link="RL_link4"/>
    <axis xyz="0 0 0"/>
  </joint>
  <joint name="RR_theta1" type="revolute">
    <origin rpy="1.57079632679492 0 1.5707963267949" xyz="-0.111650000000003 -0.0609999999999995 -0.0144000000000178"/>
    <parent link="base_link"/>
    <child link="RR_link1"/>
    <axis xyz="0 0 -1"/>
    <limit effort="10" lower="-0.785398" upper="0.785398" velocity="3"/>
    <dynamics damping="1000.0" friction="1000.0"/>
  </joint>
  <joint name="RR_theta2" type="revolute">
    <origin rpy="1.57079631992506 1.57079572077363 -1.57079633366473" xyz="-0.0495999992169147 0.0144000000000178 0"/>
    <parent link="RR_link1"/>
    <child link="RR_link2"/>
    <axis xyz="0 0 1"/>
    <limit effort="10" lower="-3" upper="3" velocity="3"/>
    <dynamics damping="1000.0" friction="1000.0"/>
  </joint>
  <joint name="RR_theta3" type="revolute">
    <origin rpy="0 0 1.57079598438978" xyz="0.13000000353672 0 0"/>
    <parent link="RR_link2"/>
    <child link="RR_link3"/>
    <axis xyz="0 0 0.999999999999998"/>
    <limit effort="10" lower="-3" upper="3" velocity="3"/>
    <dynamics damping="1000.0" friction="1000.0"/>
  </joint>
  <joint name="RR_foot" type="fixed">
    <origin rpy="0 0 0" xyz="0.138136646352431 0 0"/>
    <parent link="RR_link3"/>
    <child link="RR_link4"/>
    <axis xyz="0 0 0"/>
  </joint>
  <gazebo>
    <plugin filename="libgazebo_ros2_control.so" name="gazebo_ros2_control">
      <parameters>/home/jarvis/magic/ROS/magbot_ws/install/magbot_gazebo/share/magbot_gazebo/config/dingo_controllers.yaml</parameters>
      <!-- <ros>
       <namespace>/dingo_controller</namespace>
     </ros> -->
    </plugin>
  </gazebo>
  <gazebo reference="base_link">
    <gravity>true</gravity>
    <sensor name="imu_sensor" type="imu">
      <always_on>true</always_on>
      <update_rate>100</update_rate>
      <visualize>true</visualize>
      <topic>__default_topic__</topic>
      <imu>
        <angular_velocity>
          <noise>
            <type>gaussian</type>
            <mean>0.0</mean>
            <stddev>0.01</stddev>
            <!-- Adjust stddev as needed -->
          </noise>
        </angular_velocity>
        <linear_acceleration>
          <noise>
            <type>gaussian</type>
            <mean>0.0</mean>
            <stddev>0.1</stddev>
            <!-- Adjust stddev as needed -->
          </noise>
        </linear_acceleration>
      </imu>
      <pose>0 0 0 0 0 0</pose>
      <plugin filename="libgazebo_ros_imu_sensor.so" name="imu_plugin">
        <ros>
          <namespace>/dingo</namespace>
          <remapping>~/out:=imu</remapping>
        </ros>
        <topicName>imu</topicName>
        <bodyName>base_link</bodyName>
        <updateRateHZ>15.0</updateRateHZ>
        <xyzOffset>0 0 0</xyzOffset>
        <rpyOffset>0 0 0</rpyOffset>
        <frameName>base_link</frameName>
      </plugin>
    </sensor>
  </gazebo>
  <gazebo>
    <plugin filename="libgazebo_ros_joint_state_publisher.so" name="joint_state_publisher">
      <ros>
        <namespace>/dingo_gazebo</namespace>
        <remapping>~/out:=joint_states</remapping>
      </ros>
      <update_rate>50</update_rate>
      <joint_name>FR_theta1</joint_name>
      <joint_name>FR_theta2</joint_name>
      <joint_name>FR_theta3</joint_name>
      <joint_name>FL_theta1</joint_name>
      <joint_name>FL_theta2</joint_name>
      <joint_name>FL_theta3</joint_name>
      <joint_name>RR_theta1</joint_name>
      <joint_name>RR_theta2</joint_name>
      <joint_name>RR_theta3</joint_name>
      <joint_name>RL_theta1</joint_name>
      <joint_name>RL_theta2</joint_name>
      <joint_name>RL_theta3</joint_name>
    </plugin>
  </gazebo>
  <!-- FR4 friction -->
  <gazebo reference="FR_link4">
    <mu1>1.0</mu1>
    <mu2>1.0</mu2>
    <min_depth>0.0002</min_depth>
    <!-- Updated to min_depth to match Gazebo naming -->
    <kp>1000000.0</kp>
    <!-- Removed value attribute for ROS2 syntax -->
    <kd>100.0</kd>
    <!-- Removed value attribute for ROS2 syntax -->
  </gazebo>
  <gazebo reference="FL_link4">
    <mu1>1.0</mu1>
    <mu2>1.0</mu2>
    <min_depth>0.0002</min_depth>
    <kp>1000000.0</kp>
    <kd>100.0</kd>
  </gazebo>
  <gazebo reference="RR_link4">
    <mu1>1.0</mu1>
    <mu2>1.0</mu2>
    <min_depth>0.0002</min_depth>
    <kp>1000000.0</kp>
    <kd>100.0</kd>
  </gazebo>
  <gazebo reference="RL_link4">
    <mu1>1.0</mu1>
    <mu2>1.0</mu2>
    <min_depth>0.0002</min_depth>
    <kp>1000000.0</kp>
    <kd>100.0</kd>
  </gazebo>
  <!-- <gazebo reference="FR_link4">
    <mu1>1.0</mu1>
    <mu2>1.0</mu2>
    <minDepth>0.0002</minDepth>
    <kp  value="1000000.0"/>
    <kd  value="100.0"/>
  </gazebo>

  <gazebo reference="FL_link4">
    <mu1>1.0</mu1>
    <mu2>1.0</mu2>
    <minDepth>0.0002</minDepth>
    <kp  value="1000000.0"/>
    <kd  value="100.0"/>
  </gazebo>

  <gazebo reference="RR_link4">
    <mu1>1.0</mu1>
    <mu2>1.0</mu2>
    <minDepth>0.0002</minDepth>
    <kp  value="1000000.0"/>
    <kd  value="100.0"/>
  </gazebo>

  <gazebo reference="RL_link4">
    <mu1>1.0</mu1>
    <mu2>1.0</mu2>
    <minDepth>0.0002</minDepth>
    <kp  value="1000000.0"/>
    <kd  value="100.0"/>
  </gazebo> -->
  <ros2_control name="DingoRobotSystem" type="system">
    <hardware>
      <plugin>gazebo_ros2_control/GazeboSystem</plugin>
    </hardware>
    <!-- FL Joint Group -->
    <joint name="FL_theta1">
      <command_interface name="position"/>
      <state_interface name="position"/>
      <state_interface name="velocity"/>
      <state_interface name="effort"/>
      <param name="initial_position">0.0</param>
    </joint>
    <joint name="FL_theta2">
      <command_interface name="position"/>
      <state_interface name="position"/>
      <state_interface name="velocity"/>
      <state_interface name="effort"/>
      <param name="initial_position">0.0</param>
    </joint>
    <joint name="FL_theta3">
      <command_interface name="position"/>
      <state_interface name="position"/>
      <state_interface name="velocity"/>
      <state_interface name="effort"/>
      <param name="initial_position">0.0</param>
    </joint>
    <!-- FR Joint Group -->
    <joint name="FR_theta1">
      <command_interface name="position"/>
      <state_interface name="position"/>
      <state_interface name="velocity"/>
      <state_interface name="effort"/>
      <param name="initial_position">0.0</param>
    </joint>
    <joint name="FR_theta2">
      <command_interface name="position"/>
      <state_interface name="position"/>
      <state_interface name="velocity"/>
      <state_interface name="effort"/>
      <param name="initial_position">0.0</param>
    </joint>
    <joint name="FR_theta3">
      <command_interface name="position"/>
      <state_interface name="position"/>
      <state_interface name="velocity"/>
      <state_interface name="effort"/>
      <param name="initial_position">0.0</param>
    </joint>
    <!-- RR Joint Group -->
    <joint name="RR_theta1">
      <command_interface name="position"/>
      <state_interface name="position"/>
      <state_interface name="velocity"/>
      <state_interface name="effort"/>
      <param name="initial_position">0.0</param>
    </joint>
    <joint name="RR_theta2">
      <command_interface name="position"/>
      <state_interface name="position"/>
      <state_interface name="velocity"/>
      <state_interface name="effort"/>
      <param name="initial_position">0.0</param>
    </joint>
    <joint name="RR_theta3">
      <command_interface name="position"/>
      <state_interface name="position"/>
      <state_interface name="velocity"/>
      <state_interface name="effort"/>
      <param name="initial_position">0.0</param>
    </joint>
    <!-- RL Joint Group -->
    <joint name="RL_theta1">
      <command_interface name="position"/>
      <state_interface name="position"/>
      <state_interface name="velocity"/>
      <state_interface name="effort"/>
      <param name="initial_position">0.0</param>
    </joint>
    <joint name="RL_theta2">
      <command_interface name="position"/>
      <state_interface name="position"/>
      <state_interface name="velocity"/>
      <state_interface name="effort"/>
      <param name="initial_position">0.0</param>
    </joint>
    <joint name="RL_theta3">
      <command_interface name="position"/>
      <state_interface name="position"/>
      <state_interface name="velocity"/>
      <state_interface name="effort"/>
      <param name="initial_position">0.0</param>
    </joint>
    <!-- Transmissions -->
    <transmission name="tran1">
      <plugin>transmission_interface/SimpleTransmission</plugin>
      <actuator name="motor1" role="actuator1">
        <mechanical_reduction>5</mechanical_reduction>
      </actuator>
      <joint name="FR_theta1" role="joint1">
        <offset>0.0</offset>
      </joint>
    </transmission>
    <transmission name="tran2">
      <plugin>transmission_interface/SimpleTransmission</plugin>
      <actuator name="motor2" role="actuator1">
        <mechanical_reduction>5</mechanical_reduction>
      </actuator>
      <joint name="FR_theta2" role="joint1">
        <offset>0.0</offset>
      </joint>
    </transmission>
    <transmission name="tran3">
      <plugin>transmission_interface/SimpleTransmission</plugin>
      <actuator name="motor3" role="actuator1">
        <mechanical_reduction>5</mechanical_reduction>
      </actuator>
      <joint name="FR_theta3" role="joint1">
        <offset>0.0</offset>
      </joint>
    </transmission>
    <transmission name="tran4">
      <plugin>transmission_interface/SimpleTransmission</plugin>
      <actuator name="motor4" role="actuator1">
        <mechanical_reduction>5</mechanical_reduction>
      </actuator>
      <joint name="FL_theta1" role="joint1">
        <offset>0.0</offset>
      </joint>
    </transmission>
    <transmission name="tran5">
      <plugin>transmission_interface/SimpleTransmission</plugin>
      <actuator name="motor5" role="actuator1">
        <mechanical_reduction>5</mechanical_reduction>
      </actuator>
      <joint name="FL_theta2" role="joint1">
        <offset>0.0</offset>
      </joint>
    </transmission>
    <transmission name="tran6">
      <plugin>transmission_interface/SimpleTransmission</plugin>
      <actuator name="motor6" role="actuator1">
        <mechanical_reduction>5</mechanical_reduction>
      </actuator>
      <joint name="FL_theta3" role="joint1">
        <offset>0.0</offset>
      </joint>
    </transmission>
    <transmission name="tran7">
      <plugin>transmission_interface/SimpleTransmission</plugin>
      <actuator name="motor7" role="actuator1">
        <mechanical_reduction>5</mechanical_reduction>
      </actuator>
      <joint name="RR_theta1" role="joint1">
        <offset>0.0</offset>
      </joint>
    </transmission>
    <transmission name="tran8">
      <plugin>transmission_interface/SimpleTransmission</plugin>
      <actuator name="motor8" role="actuator1">
        <mechanical_reduction>5</mechanical_reduction>
      </actuator>
      <joint name="RR_theta2" role="joint1">
        <offset>0.0</offset>
      </joint>
    </transmission>
    <transmission name="tran9">
      <plugin>transmission_interface/SimpleTransmission</plugin>
      <actuator name="motor9" role="actuator1">
        <mechanical_reduction>5</mechanical_reduction>
      </actuator>
      <joint name="RR_theta3" role="joint1">
        <offset>0.0</offset>
      </joint>
    </transmission>
    <transmission name="tran10">
      <plugin>transmission_interface/SimpleTransmission</plugin>
      <actuator name="motor10" role="actuator1">
        <mechanical_reduction>5</mechanical_reduction>
      </actuator>
      <joint name="RL_theta1" role="joint1">
        <offset>0.0</offset>
      </joint>
    </transmission>
    <transmission name="tran11">
      <plugin>transmission_interface/SimpleTransmission</plugin>
      <actuator name="motor11" role="actuator1">
        <mechanical_reduction>5</mechanical_reduction>
      </actuator>
      <joint name="RL_theta2" role="joint1">
        <offset>0.0</offset>
      </joint>
    </transmission>
    <transmission name="tran12">
      <plugin>transmission_interface/SimpleTransmission</plugin>
      <actuator name="motor12" role="actuator1">
        <mechanical_reduction>5</mechanical_reduction>
      </actuator>
      <joint name="RL_theta3" role="joint1">
        <offset>0.0</offset>
      </joint>
    </transmission>
  </ros2_control>
</robot>
