<?xml version="1.0" ?>
<!-- =================================================================================== -->
<!-- |    This document was autogenerated by xacro from dingo.urdf.xacro               | -->
<!-- |    EDITING THIS FILE BY HAND IS NOT RECOMMENDED                                 | -->
<!-- =================================================================================== -->
<robot name="dingo">
  <!-- The root link can't have inertia so did this -->
  <!-- <link name="root_dummy_link" />

  <joint name="root_joint" type="fixed">
    <parent link="root_dummy_link"/>
    <child link="base_link"/>
  </joint> -->
  <!-- The root link can't have inertia so did this -->
  <!-- base_link -->
  <link name="base_link">
    <!-- <inertial>
      <origin
        xyz="0 0 0"
        rpy="0 0 0" />
      <mass
        value="0.81776" />
      <inertia
        ixx="0.00058474"
        ixy="-1.0045E-06"
        ixz="1.0886E-08"
        iyy="0.00029699"
        iyz="3.2027E-08"
        izz="0.00063853" />
    </inertial> -->
    <inertial>
      <origin xyz="-0.02679290 -0.00012097 0.00457177"/>
      <mass value="5.0000000"/>
      <inertia ixx="0.00732760" ixy="-0.00000000" ixz="0.00021940" iyy="0.02995798" iyz="-0.00000002" izz="0.03298004"/>
    </inertial>
    <visual>
      <origin rpy="0 0 0" xyz="0 0 0"/>
      <geometry>
        <mesh filename="package://magbot_gazebo/description/meshes/base_link.dae"/>
      </geometry>
      <material name="">
        <color rgba="0.15294 0.78431 0.96078 1"/>
      </material>
    </visual>
    <collision>
      <origin rpy="0 0 0" xyz="0 0 0"/>
      <geometry>
        <mesh filename="package://magbot_gazebo/description/meshes/base_collision.STL"/>
      </geometry>
    </collision>
  </link>
  <!-- FL_link1 -->
  <link name="FL_link1">
    <inertial>
      <origin xyz="0 0 0"/>
      <mass value="0.30000000"/>
      <inertia ixx="0.00019300" ixy="0.00000000" ixz="0.00000000" iyy="0.00014890" iyz="0.00000000" izz="0.00012410"/>
    </inertial>
    <visual>
      <origin rpy="0 0 0" xyz="0 0 0"/>
      <geometry>
        <mesh filename="package://magbot_gazebo/description/meshes/FL_link1.dae"/>
      </geometry>
      <material name="">
        <color rgba="0.15294 0.78431 0.96078 1"/>
      </material>
    </visual>
    <collision>
      <origin rpy="0 0 0" xyz="0 0 0"/>
      <geometry>
        <mesh filename="package://magbot_gazebo/description/meshes/L_link1_collision.STL"/>
      </geometry>
    </collision>
  </link>
  <!-- FL_link2 -->
  <link name="FL_link2">
    <inertial>
      <origin xyz="0 0 0"/>
      <mass value="0.10000000"/>
      <inertia ixx="0.00000700" ixy="0.00000000" ixz="0.00000444" iyy="0.00017260" iyz="0.00000000" izz="0.00017568"/>
    </inertial>
    <visual>
      <origin rpy="0 0 0" xyz="0 0 0"/>
      <geometry>
        <mesh filename="package://magbot_gazebo/description/meshes/L_link2.dae"/>
      </geometry>
      <material name="">
        <color rgba="0.15294 0.78431 0.96078 1"/>
      </material>
    </visual>
    <collision>
      <origin rpy="0 0 0" xyz="0 0 0"/>
      <geometry>
        <mesh filename="package://magbot_gazebo/description/meshes/L_link2_collision.STL"/>
      </geometry>
    </collision>
  </link>
  <!-- FL_link3 -->
  <link name="FL_link3">
    <inertial>
      <origin xyz="0 0 0"/>
      <mass value="0.10000000"/>
      <inertia ixx="0.00000936" ixy="-0.00001360" ixz="-0.00000319" iyy="0.00019747" iyz="-0.00000027" izz="0.00019702"/>
    </inertial>
    <visual>
      <origin rpy="0 0 0" xyz="0 0 0"/>
      <geometry>
        <mesh filename="package://magbot_gazebo/description/meshes/L_link3.dae"/>
      </geometry>
      <material name="">
        <color rgba="0.15294 0.78431 0.96078 1"/>
      </material>
    </visual>
    <collision>
      <origin rpy="0 0 0" xyz="0 0 0"/>
      <geometry>
        <mesh filename="package://magbot_gazebo/description/meshes/L_link3_collision.STL"/>
      </geometry>
    </collision>
  </link>
  <!-- FL_link4 -->
  <link name="FL_link4">
    <inertial>
      <origin xyz="0 0 0"/>
      <mass value="0.02000000"/>
      <inertia ixx="0.00000060" ixy="-0.00000013" ixz="0.00000000" iyy="0.00000058" iyz="0.00000000" izz="0.00000045"/>
    </inertial>
    <visual>
      <origin rpy="0 0 0" xyz="0 0 0"/>
      <geometry>
        <mesh filename="package://magbot_gazebo/description/meshes/link4.dae"/>
      </geometry>
      <material name="">
        <color rgba="0.15294 0.78431 0.96078 1"/>
      </material>
    </visual>
    <collision>
      <origin rpy="0 0 0" xyz="0 0 0"/>
      <geometry>
        <mesh filename="package://magbot_gazebo/description/meshes/link4_collision.STL"/>
      </geometry>
    </collision>
  </link>
  <!-- FR_link1 -->
  <link name="FR_link1">
    <inertial>
      <origin xyz="0 0 0"/>
      <mass value="0.30000000"/>
      <inertia ixx="0.00019300" ixy="0.00000000" ixz="0.00000000" iyy="0.00014890" iyz="0.00000000" izz="0.00012410"/>
    </inertial>
    <visual>
      <origin rpy="0 0 0" xyz="0 0 0"/>
      <geometry>
        <mesh filename="package://magbot_gazebo/description/meshes/FR_link1.dae"/>
      </geometry>
      <material name="">
        <color rgba="0.15294 0.78431 0.96078 1"/>
      </material>
    </visual>
    <collision>
      <origin rpy="0 0 0" xyz="0 0 0"/>
      <geometry>
        <mesh filename="package://magbot_gazebo/description/meshes/R_link1_collision.STL"/>
      </geometry>
    </collision>
  </link>
  <!-- FR_link2 -->
  <link name="FR_link2">
    <inertial>
      <origin xyz="0 0 0"/>
      <mass value="0.10000000"/>
      <inertia ixx="0.00000700" ixy="0.00000000" ixz="0.00000444" iyy="0.00017260" iyz="0.00000000" izz="0.00017568"/>
    </inertial>
    <visual>
      <origin rpy="0 0 0" xyz="0 0 0"/>
      <geometry>
        <mesh filename="package://magbot_gazebo/description/meshes/R_link2.dae"/>
      </geometry>
      <material name="">
        <color rgba="0.15294 0.78431 0.96078 1"/>
      </material>
    </visual>
    <collision>
      <origin rpy="0 0 0" xyz="0 0 0"/>
      <geometry>
        <mesh filename="package://magbot_gazebo/description/meshes/R_link2_collision.STL"/>
      </geometry>
    </collision>
  </link>
  <!-- FR_link3 -->
  <link name="FR_link3">
    <inertial>
      <origin xyz="0 0 0"/>
      <mass value="0.10000000"/>
      <inertia ixx="0.00000936" ixy="-0.00001360" ixz="-0.00000319" iyy="0.00019747" iyz="-0.00000027" izz="0.00019702"/>
    </inertial>
    <visual>
      <origin rpy="0 0 0" xyz="0 0 0"/>
      <geometry>
        <mesh filename="package://magbot_gazebo/description/meshes/R_link3.dae"/>
      </geometry>
      <material name="">
        <color rgba="0.15294 0.78431 0.96078 1"/>
      </material>
    </visual>
    <collision>
      <origin rpy="0 0 0" xyz="0 0 0"/>
      <geometry>
        <mesh filename="package://magbot_gazebo/description/meshes/R_link3_collision.STL"/>
      </geometry>
    </collision>
  </link>
  <!-- FR_link4 -->
  <link name="FR_link4">
    <inertial>
      <origin xyz="0 0 0"/>
      <mass value="0.02000000"/>
      <inertia ixx="0.00000060" ixy="-0.00000013" ixz="0.00000000" iyy="0.00000058" iyz="0.00000000" izz="0.00000045"/>
    </inertial>
    <visual>
      <origin rpy="0 0 0" xyz="0 0 0"/>
      <geometry>
        <mesh filename="package://magbot_gazebo/description/meshes/link4.dae"/>
      </geometry>
      <material name="">
        <color rgba="0.15294 0.78431 0.96078 1"/>
      </material>
    </visual>
    <collision>
      <origin rpy="0 0 0" xyz="0 0 0"/>
      <geometry>
        <mesh filename="package://magbot_gazebo/description/meshes/link4_collision.STL"/>
      </geometry>
    </collision>
  </link>
  <!-- RL_link1 -->
  <link name="RL_link1">
    <inertial>
      <origin xyz="0 0 0"/>
      <mass value="0.30000000"/>
      <inertia ixx="0.00019300" ixy="0.00000000" ixz="0.00000000" iyy="0.00014890" iyz="0.00000000" izz="0.00012410"/>
    </inertial>
    <visual>
      <origin rpy="0 0 0" xyz="0 0 0"/>
      <geometry>
        <mesh filename="package://magbot_gazebo/description/meshes/RL_link1.dae"/>
      </geometry>
      <material name="">
        <color rgba="0.15294 0.78431 0.96078 1"/>
      </material>
    </visual>
    <collision>
      <origin rpy="0 0 0" xyz="0 0 0"/>
      <geometry>
        <mesh filename="package://magbot_gazebo/description/meshes/L_link1_collision.STL"/>
      </geometry>
    </collision>
  </link>
  <!-- RL_link2 -->
  <link name="RL_link2">
    <inertial>
      <origin xyz="0 0 0"/>
      <mass value="0.10000000"/>
      <inertia ixx="0.00000700" ixy="0.00000000" ixz="0.00000444" iyy="0.00017260" iyz="0.00000000" izz="0.00017568"/>
    </inertial>
    <visual>
      <origin rpy="0 0 0" xyz="0 0 0"/>
      <geometry>
        <mesh filename="package://magbot_gazebo/description/meshes/L_link2.dae"/>
      </geometry>
      <material name="">
        <color rgba="0.15294 0.78431 0.96078 1"/>
      </material>
    </visual>
    <collision>
      <origin rpy="0 0 0" xyz="0 0 0"/>
      <geometry>
        <mesh filename="package://magbot_gazebo/description/meshes/L_link2_collision.STL"/>
      </geometry>
    </collision>
  </link>
  <!-- RL_link3 -->
  <link name="RL_link3">
    <inertial>
      <origin xyz="0 0 0"/>
      <mass value="0.10000000"/>
      <inertia ixx="0.00000936" ixy="-0.00001360" ixz="-0.00000319" iyy="0.00019747" iyz="-0.00000027" izz="0.00019702"/>
    </inertial>
    <visual>
      <origin rpy="0 0 0" xyz="0 0 0"/>
      <geometry>
        <mesh filename="package://magbot_gazebo/description/meshes/L_link3.dae"/>
      </geometry>
      <material name="">
        <color rgba="0.15294 0.78431 0.96078 1"/>
      </material>
    </visual>
    <collision>
      <origin rpy="0 0 0" xyz="0 0 0"/>
      <geometry>
        <mesh filename="package://magbot_gazebo/description/meshes/L_link3_collision.STL"/>
      </geometry>
    </collision>
  </link>
  <!-- RL_link4 -->
  <link name="RL_link4">
    <inertial>
      <origin xyz="0 0 0"/>
      <mass value="0.02000000"/>
      <inertia ixx="0.00000060" ixy="-0.00000013" ixz="0.00000000" iyy="0.00000058" iyz="0.00000000" izz="0.00000045"/>
    </inertial>
    <visual>
      <origin rpy="0 0 0" xyz="0 0 0"/>
      <geometry>
        <mesh filename="package://magbot_gazebo/description/meshes/link4.dae"/>
      </geometry>
      <material name="">
        <color rgba="0.15294 0.78431 0.96078 1"/>
      </material>
    </visual>
    <collision>
      <origin rpy="0 0 0" xyz="0 0 0"/>
      <geometry>
        <mesh filename="package://magbot_gazebo/description/meshes/link4_collision.STL"/>
      </geometry>
    </collision>
  </link>
  <!-- RR_link1 -->
  <link name="RR_link1">
    <inertial>
      <origin xyz="0 0 0"/>
      <mass value="0.30000000"/>
      <inertia ixx="0.00019300" ixy="0.00000000" ixz="0.00000000" iyy="0.00014890" iyz="0.00000000" izz="0.00012410"/>
    </inertial>
    <visual>
      <origin rpy="0 0 0" xyz="0 0 0"/>
      <geometry>
        <mesh filename="package://magbot_gazebo/description/meshes/RR_link1.dae"/>
      </geometry>
      <material name="">
        <color rgba="0.15294 0.78431 0.96078 1"/>
      </material>
    </visual>
    <collision>
      <origin rpy="0 0 0" xyz="0 0 0"/>
      <geometry>
        <mesh filename="package://magbot_gazebo/description/meshes/R_link1_collision.STL"/>
      </geometry>
    </collision>
  </link>
  <!-- RR_link2 -->
  <link name="RR_link2">
    <inertial>
      <origin xyz="0 0 0"/>
      <mass value="0.10000000"/>
      <inertia ixx="0.00000700" ixy="0.00000000" ixz="0.00000444" iyy="0.00017260" iyz="0.00000000" izz="0.00017568"/>
    </inertial>
    <visual>
      <origin rpy="0 0 0" xyz="0 0 0"/>
      <geometry>
        <mesh filename="package://magbot_gazebo/description/meshes/R_link2.dae"/>
      </geometry>
      <material name="">
        <color rgba="0.15294 0.78431 0.96078 1"/>
      </material>
    </visual>
    <collision>
      <origin rpy="0 0 0" xyz="0 0 0"/>
      <geometry>
        <mesh filename="package://magbot_gazebo/description/meshes/R_link2_collision.STL"/>
      </geometry>
    </collision>
  </link>
  <!-- RR_link3 -->
  <link name="RR_link3">
    <inertial>
      <origin xyz="0 0 0"/>
      <mass value="0.10000000"/>
      <inertia ixx="0.00000936" ixy="-0.00001360" ixz="-0.00000319" iyy="0.00019747" iyz="-0.00000027" izz="0.00019702"/>
    </inertial>
    <visual>
      <origin rpy="0 0 0" xyz="0 0 0"/>
      <geometry>
        <mesh filename="package://magbot_gazebo/description/meshes/R_link3.dae"/>
      </geometry>
      <material name="">
        <color rgba="0.15294 0.78431 0.96078 1"/>
      </material>
    </visual>
    <collision>
      <origin rpy="0 0 0" xyz="0 0 0"/>
      <geometry>
        <mesh filename="package://magbot_gazebo/description/meshes/R_link3_collision.STL"/>
      </geometry>
    </collision>
  </link>
  <!-- RR_link4 -->
  <link name="RR_link4">
    <inertial>
      <origin xyz="0 0 0"/>
      <mass value="0.02000000"/>
      <inertia ixx="0.00000060" ixy="-0.00000013" ixz="0.00000000" iyy="0.00000058" iyz="0.00000000" izz="0.00000045"/>
    </inertial>
    <visual>
      <origin rpy="0 0 0" xyz="0 0 0"/>
      <geometry>
        <mesh filename="package://magbot_gazebo/description/meshes/link4.dae"/>
      </geometry>
      <material name="">
        <color rgba="0.15294 0.78431 0.96078 1"/>
      </material>
    </visual>
    <collision>
      <origin rpy="0 0 0" xyz="0 0 0"/>
      <geometry>
        <mesh filename="package://magbot_gazebo/description/meshes/link4_collision.STL"/>
      </geometry>
    </collision>
  </link>
  <!-- JOINTS -->
  <joint name="FL_theta1" type="revolute">
    <origin rpy="1.5708 0 1.5708" xyz="0.11165 0.061 -0.0144"/>
    <parent link="base_link"/>
    <child link="FL_link1"/>
    <axis xyz="0 0 1"/>
    <limit effort="10" lower="-0.785398" upper="0.785398" velocity="3"/>
    <!-- <joint_properties damping="1000.0" friction="1000.0"/> -->
    <dynamics damping="1000.0" friction="1000.0"/>
  </joint>
  <joint name="FL_theta2" type="revolute">
    <origin rpy="1.57079634307336 1.57079568414183 -1.57079631051644" xyz="0.0496000007984339 0.014400000013256 0"/>
    <parent link="FL_link1"/>
    <child link="FL_link2"/>
    <axis xyz="0 0 1"/>
    <limit effort="10" lower="-3" upper="3" velocity="3"/>
    <!-- <joint_properties damping="1000.0" friction="1000.0"/> -->
    <dynamics damping="1000.0" friction="1000.0"/>
  </joint>
  <joint name="FL_theta3" type="revolute">
    <origin rpy="0 0 1.57079594774422" xyz="0.129999999999897 0 0"/>
    <parent link="FL_link2"/>
    <child link="FL_link3"/>
    <axis xyz="0 0 1"/>
    <limit effort="10" lower="-3" upper="3" velocity="3"/>
    <!-- <joint_properties damping="1000.0" friction="1000.0"/> -->
    <dynamics damping="1000.0" friction="1000.0"/>
  </joint>
  <joint name="FL_foot" type="fixed">
    <origin rpy="0 0 0" xyz="0.138136646352288 0 0"/>
    <parent link="FL_link3"/>
    <child link="FL_link4"/>
    <axis xyz="0 0 0"/>
  </joint>
  <joint name="FR_theta1" type="revolute">
    <origin rpy="1.57079632679492 0 1.5707963267949" xyz="0.111650000000002 -0.0609999999999988 -0.0144000000000242"/>
    <parent link="base_link"/>
    <child link="FR_link1"/>
    <axis xyz="0 0 -1"/>
    <limit effort="10" lower="-0.785398" upper="0.785398" velocity="3"/>
    <!-- <joint_properties damping="1000.0" friction="1000.0"/> -->
    <dynamics damping="1000.0" friction="1000.0"/>
  </joint>
  <joint name="FR_theta2" type="revolute">
    <origin rpy="1.57079632309575 1.57079572077363 -1.57079633049404" xyz="-0.0495999992169121 0.0144000000000242 0"/>
    <parent link="FR_link1"/>
    <child link="FR_link2"/>
    <axis xyz="0 0 1"/>
    <limit effort="10" lower="-3" upper="3" velocity="3"/>
    <!-- <joint_properties damping="1000.0" friction="1000.0"/> -->
    <dynamics damping="1000.0" friction="1000.0"/>
  </joint>
  <joint name="FR_theta3" type="revolute">
    <origin rpy="0 0 1.57079598438978" xyz="0.13000000353672 0 0"/>
    <parent link="FR_link2"/>
    <child link="FR_link3"/>
    <axis xyz="0 0 1"/>
    <limit effort="10" lower="-3" upper="3" velocity="3"/>
    <!-- <joint_properties damping="1000.0" friction="1000.0"/> -->
    <dynamics damping="1000.0" friction="1000.0"/>
  </joint>
  <joint name="FR_foot" type="fixed">
    <origin rpy="0 0 0" xyz="0.13813664635243 0 0"/>
    <parent link="FR_link3"/>
    <child link="FR_link4"/>
    <axis xyz="0 0 0"/>
  </joint>
  <joint name="RL_theta1" type="revolute">
    <origin rpy="1.5708 0 1.5708" xyz="-0.11165 0.061 -0.0144"/>
    <parent link="base_link"/>
    <child link="RL_link1"/>
    <axis xyz="0 0 1"/>
    <limit effort="10" lower="-0.785398" upper="0.785398" velocity="3"/>
    <!-- <joint_properties damping="1000.0" friction="1000.0"/> -->
    <dynamics damping="1000.0" friction="1000.0"/>
  </joint>
  <joint name="RL_theta2" type="revolute">
    <origin rpy="1.5707963301177 1.57079568414183 -1.57079632347209" xyz="0.0496000007984574 0.014399999996394 0"/>
    <parent link="RL_link1"/>
    <child link="RL_link2"/>
    <axis xyz="0 0 1"/>
    <limit effort="10" lower="-3" upper="3" velocity="3"/>
    <!-- <joint_properties damping="1000.0" friction="1000.0"/> -->
    <dynamics damping="1000.0" friction="1000.0"/>
  </joint>
  <joint name="RL_theta3" type="revolute">
    <origin rpy="0 0 1.57079594787326" xyz="0.129999999994849 0 0"/>
    <parent link="RL_link2"/>
    <child link="RL_link3"/>
    <axis xyz="0 0 0.999999999999979"/>
    <limit effort="10" lower="-3" upper="3" velocity="3"/>
    <!-- <joint_properties damping="1000.0" friction="1000.0"/> -->
    <dynamics damping="1000.0" friction="1000.0"/>
  </joint>
  <joint name="RL_foot" type="fixed">
    <origin rpy="0 0 0" xyz="0.138136646352323 0 0"/>
    <parent link="RL_link3"/>
    <child link="RL_link4"/>
    <axis xyz="0 0 0"/>
  </joint>
  <joint name="RR_theta1" type="revolute">
    <origin rpy="1.57079632679492 0 1.5707963267949" xyz="-0.111650000000003 -0.0609999999999995 -0.0144000000000178"/>
    <parent link="base_link"/>
    <child link="RR_link1"/>
    <axis xyz="0 0 -1"/>
    <limit effort="10" lower="-0.785398" upper="0.785398" velocity="3"/>
    <!-- <joint_properties damping="1000.0" friction="1000.0"/> -->
    <dynamics damping="1000.0" friction="1000.0"/>
  </joint>
  <joint name="RR_theta2" type="revolute">
    <origin rpy="1.57079631992506 1.57079572077363 -1.57079633366473" xyz="-0.0495999992169147 0.0144000000000178 0"/>
    <parent link="RR_link1"/>
    <child link="RR_link2"/>
    <axis xyz="0 0 1"/>
    <limit effort="10" lower="-3" upper="3" velocity="3"/>
    <!-- <joint_properties damping="1000.0" friction="1000.0"/> -->
    <dynamics damping="1000.0" friction="1000.0"/>
  </joint>
  <joint name="RR_theta3" type="revolute">
    <origin rpy="0 0 1.57079598438978" xyz="0.13000000353672 0 0"/>
    <parent link="RR_link2"/>
    <child link="RR_link3"/>
    <axis xyz="0 0 0.999999999999998"/>
    <limit effort="10" lower="-3" upper="3" velocity="3"/>
    <!-- <joint_properties damping="1000.0" friction="1000.0"/> -->
    <dynamics damping="1000.0" friction="1000.0"/>
  </joint>
  <joint name="RR_foot" type="fixed">
    <origin rpy="0 0 0" xyz="0.138136646352431 0 0"/>
    <parent link="RR_link3"/>
    <child link="RR_link4"/>
    <axis xyz="0 0 0"/>
  </joint>
  <gazebo>
    <plugin filename="libgazebo_ros2_control.so" name="gazebo_ros2_control">
      <parameters>/home/jarvis/magic/ROS/magbot_ws/install/magbot_gazebo/share/magbot_gazebo/config/dingo_controllers.yaml</parameters>
      <!-- <ros>
       <namespace>/dingo_controller</namespace>
     </ros> -->
    </plugin>
  </gazebo>
  <gazebo reference="base_link">
    <gravity>true</gravity>
    <sensor name="imu_sensor" type="imu">
      <always_on>true</always_on>
      <update_rate>100</update_rate>
      <visualize>true</visualize>
      <topic>__default_topic__</topic>
      <imu>
        <angular_velocity>
          <noise>
            <type>gaussian</type>
            <mean>0.0</mean>
            <stddev>0.01</stddev>
            <!-- Adjust stddev as needed -->
          </noise>
        </angular_velocity>
        <linear_acceleration>
          <noise>
            <type>gaussian</type>
            <mean>0.0</mean>
            <stddev>0.1</stddev>
            <!-- Adjust stddev as needed -->
          </noise>
        </linear_acceleration>
      </imu>
      <pose>0 0 0 0 0 0</pose>
      <plugin filename="libgazebo_ros_imu_sensor.so" name="imu_plugin">
        <ros>
          <namespace>/dingo</namespace>
          <remapping>~/out:=imu</remapping>
        </ros>
        <topicName>imu</topicName>
        <bodyName>base_link</bodyName>
        <updateRateHZ>15.0</updateRateHZ>
        <xyzOffset>0 0 0</xyzOffset>
        <rpyOffset>0 0 0</rpyOffset>
        <frameName>base_link</frameName>
      </plugin>
    </sensor>
  </gazebo>
  <gazebo>
    <plugin filename="libgazebo_ros_joint_state_publisher.so" name="joint_state_publisher">
      <ros>
        <namespace>/dingo_gazebo</namespace>
        <remapping>~/out:=joint_states</remapping>
      </ros>
      <update_rate>50</update_rate>
      <joint_name>FR_theta1</joint_name>
      <joint_name>FR_theta2</joint_name>
      <joint_name>FR_theta3</joint_name>
      <joint_name>FL_theta1</joint_name>
      <joint_name>FL_theta2</joint_name>
      <joint_name>FL_theta3</joint_name>
      <joint_name>RR_theta1</joint_name>
      <joint_name>RR_theta2</joint_name>
      <joint_name>RR_theta3</joint_name>
      <joint_name>RL_theta1</joint_name>
      <joint_name>RL_theta2</joint_name>
      <joint_name>RL_theta3</joint_name>
    </plugin>
  </gazebo>
  <!-- FR4 friction -->
  <gazebo reference="FR_link4">
    <mu1>1.0</mu1>
    <mu2>1.0</mu2>
    <min_depth>0.0002</min_depth>
    <!-- Updated to min_depth to match Gazebo naming -->
    <kp>1000000.0</kp>
    <!-- Removed value attribute for ROS2 syntax -->
    <kd>100.0</kd>
    <!-- Removed value attribute for ROS2 syntax -->
  </gazebo>
  <gazebo reference="FL_link4">
    <mu1>1.0</mu1>
    <mu2>1.0</mu2>
    <min_depth>0.0002</min_depth>
    <kp>1000000.0</kp>
    <kd>100.0</kd>
  </gazebo>
  <gazebo reference="RR_link4">
    <mu1>1.0</mu1>
    <mu2>1.0</mu2>
    <min_depth>0.0002</min_depth>
    <kp>1000000.0</kp>
    <kd>100.0</kd>
  </gazebo>
  <gazebo reference="RL_link4">
    <mu1>1.0</mu1>
    <mu2>1.0</mu2>
    <min_depth>0.0002</min_depth>
    <kp>1000000.0</kp>
    <kd>100.0</kd>
  </gazebo>
  <!-- <gazebo reference="FR_link4">
    <mu1>1.0</mu1>
    <mu2>1.0</mu2>
    <minDepth>0.0002</minDepth>
    <kp  value="1000000.0"/>
    <kd  value="100.0"/>
  </gazebo>

  <gazebo reference="FL_link4">
    <mu1>1.0</mu1>
    <mu2>1.0</mu2>
    <minDepth>0.0002</minDepth>
    <kp  value="1000000.0"/>
    <kd  value="100.0"/>
  </gazebo>

  <gazebo reference="RR_link4">
    <mu1>1.0</mu1>
    <mu2>1.0</mu2>
    <minDepth>0.0002</minDepth>
    <kp  value="1000000.0"/>
    <kd  value="100.0"/>
  </gazebo>

  <gazebo reference="RL_link4">
    <mu1>1.0</mu1>
    <mu2>1.0</mu2>
    <minDepth>0.0002</minDepth>
    <kp  value="1000000.0"/>
    <kd  value="100.0"/>
  </gazebo> -->
  <ros2_control name="DingoRobotSystem" type="system">
    <hardware>
      <plugin>gazebo_ros2_control/GazeboSystem</plugin>
    </hardware>
    <!-- FL Joint Group -->
    <joint name="FL_theta1">
      <command_interface name="position"/>
      <state_interface name="position"/>
      <state_interface name="velocity"/>
      <state_interface name="effort"/>
      <param name="initial_position">0.0</param>
    </joint>
    <joint name="FL_theta2">
      <command_interface name="position"/>
      <state_interface name="position"/>
      <state_interface name="velocity"/>
      <state_interface name="effort"/>
      <param name="initial_position">0.0</param>
    </joint>
    <joint name="FL_theta3">
      <command_interface name="position"/>
      <state_interface name="position"/>
      <state_interface name="velocity"/>
      <state_interface name="effort"/>
      <param name="initial_position">0.0</param>
    </joint>
    <!-- FR Joint Group -->
    <joint name="FR_theta1">
      <command_interface name="position"/>
      <state_interface name="position"/>
      <state_interface name="velocity"/>
      <state_interface name="effort"/>
      <param name="initial_position">0.0</param>
    </joint>
    <joint name="FR_theta2">
      <command_interface name="position"/>
      <state_interface name="position"/>
      <state_interface name="velocity"/>
      <state_interface name="effort"/>
      <param name="initial_position">0.0</param>
    </joint>
    <joint name="FR_theta3">
      <command_interface name="position"/>
      <state_interface name="position"/>
      <state_interface name="velocity"/>
      <state_interface name="effort"/>
      <param name="initial_position">0.0</param>
    </joint>
    <!-- RR Joint Group -->
    <joint name="RR_theta1">
      <command_interface name="position"/>
      <state_interface name="position"/>
      <state_interface name="velocity"/>
      <state_interface name="effort"/>
      <param name="initial_position">0.0</param>
    </joint>
    <joint name="RR_theta2">
      <command_interface name="position"/>
      <state_interface name="position"/>
      <state_interface name="velocity"/>
      <state_interface name="effort"/>
      <param name="initial_position">0.0</param>
    </joint>
    <joint name="RR_theta3">
      <command_interface name="position"/>
      <state_interface name="position"/>
      <state_interface name="velocity"/>
      <state_interface name="effort"/>
      <param name="initial_position">0.0</param>
    </joint>
    <!-- RL Joint Group -->
    <joint name="RL_theta1">
      <command_interface name="position"/>
      <state_interface name="position"/>
      <state_interface name="velocity"/>
      <state_interface name="effort"/>
      <param name="initial_position">0.0</param>
    </joint>
    <joint name="RL_theta2">
      <command_interface name="position"/>
      <state_interface name="position"/>
      <state_interface name="velocity"/>
      <state_interface name="effort"/>
      <param name="initial_position">0.0</param>
    </joint>
    <joint name="RL_theta3">
      <command_interface name="position"/>
      <state_interface name="position"/>
      <state_interface name="velocity"/>
      <state_interface name="effort"/>
      <param name="initial_position">0.0</param>
    </joint>
    <!-- Transmissions -->
    <transmission name="tran1">
      <plugin>transmission_interface/SimpleTransmission</plugin>
      <actuator name="motor1" role="actuator1">
        <mechanical_reduction>5</mechanical_reduction>
      </actuator>
      <joint name="FR_theta1" role="joint1">
        <offset>0.0</offset>
      </joint>
    </transmission>
    <transmission name="tran2">
      <plugin>transmission_interface/SimpleTransmission</plugin>
      <actuator name="motor2" role="actuator1">
        <mechanical_reduction>5</mechanical_reduction>
      </actuator>
      <joint name="FR_theta2" role="joint1">
        <offset>0.0</offset>
      </joint>
    </transmission>
    <transmission name="tran3">
      <plugin>transmission_interface/SimpleTransmission</plugin>
      <actuator name="motor3" role="actuator1">
        <mechanical_reduction>5</mechanical_reduction>
      </actuator>
      <joint name="FR_theta3" role="joint1">
        <offset>0.0</offset>
      </joint>
    </transmission>
    <transmission name="tran4">
      <plugin>transmission_interface/SimpleTransmission</plugin>
      <actuator name="motor4" role="actuator1">
        <mechanical_reduction>5</mechanical_reduction>
      </actuator>
      <joint name="FL_theta1" role="joint1">
        <offset>0.0</offset>
      </joint>
    </transmission>
    <transmission name="tran5">
      <plugin>transmission_interface/SimpleTransmission</plugin>
      <actuator name="motor5" role="actuator1">
        <mechanical_reduction>5</mechanical_reduction>
      </actuator>
      <joint name="FL_theta2" role="joint1">
        <offset>0.0</offset>
      </joint>
    </transmission>
    <transmission name="tran6">
      <plugin>transmission_interface/SimpleTransmission</plugin>
      <actuator name="motor6" role="actuator1">
        <mechanical_reduction>5</mechanical_reduction>
      </actuator>
      <joint name="FL_theta3" role="joint1">
        <offset>0.0</offset>
      </joint>
    </transmission>
    <transmission name="tran7">
      <plugin>transmission_interface/SimpleTransmission</plugin>
      <actuator name="motor7" role="actuator1">
        <mechanical_reduction>5</mechanical_reduction>
      </actuator>
      <joint name="RR_theta1" role="joint1">
        <offset>0.0</offset>
      </joint>
    </transmission>
    <transmission name="tran8">
      <plugin>transmission_interface/SimpleTransmission</plugin>
      <actuator name="motor8" role="actuator1">
        <mechanical_reduction>5</mechanical_reduction>
      </actuator>
      <joint name="RR_theta2" role="joint1">
        <offset>0.0</offset>
      </joint>
    </transmission>
    <transmission name="tran9">
      <plugin>transmission_interface/SimpleTransmission</plugin>
      <actuator name="motor9" role="actuator1">
        <mechanical_reduction>5</mechanical_reduction>
      </actuator>
      <joint name="RR_theta3" role="joint1">
        <offset>0.0</offset>
      </joint>
    </transmission>
    <transmission name="tran10">
      <plugin>transmission_interface/SimpleTransmission</plugin>
      <actuator name="motor10" role="actuator1">
        <mechanical_reduction>5</mechanical_reduction>
      </actuator>
      <joint name="RL_theta1" role="joint1">
        <offset>0.0</offset>
      </joint>
    </transmission>
    <transmission name="tran11">
      <plugin>transmission_interface/SimpleTransmission</plugin>
      <actuator name="motor11" role="actuator1">
        <mechanical_reduction>5</mechanical_reduction>
      </actuator>
      <joint name="RL_theta2" role="joint1">
        <offset>0.0</offset>
      </joint>
    </transmission>
    <transmission name="tran12">
      <plugin>transmission_interface/SimpleTransmission</plugin>
      <actuator name="motor12" role="actuator1">
        <mechanical_reduction>5</mechanical_reduction>
      </actuator>
      <joint name="RL_theta3" role="joint1">
        <offset>0.0</offset>
      </joint>
    </transmission>
  </ros2_control>
</robot>
