<robot name="dingo" xmlns:xacro="http://www.ros.org/wiki/xacro">

  <xacro:include filename="$(find magbot_gazebo)/description/urdf/dingo_ros2_control.xacro" />
  <!-- Maximum torque -->
  <xacro:property name="effort_limit" value="10" />

  <!-- base_link -->
  <link
    name="base_link">

    <inertial>
      <origin
        xyz="0 0 0"
        rpy="0 0 0" />
      <mass
        value="2.2" />
      <inertia
        ixx="0.00058474"
        ixy="-1.0045E-06"
        ixz="1.0886E-08"
        iyy="0.00029699"
        iyz="3.2027E-08"
        izz="0.00063853" />
    </inertial>

    <visual>
      <origin
        xyz="0 0 0"
        rpy="0 0 0" />
      <geometry>
        <mesh
          filename="package://magbot_gazebo/description/meshes/base_link.dae" />
      </geometry>
      <material
        name="">
        <color
          rgba="0.79216 0.81961 0.93333 1" />
      </material>
    </visual>
    <collision>
      <origin
        xyz="0 0 0"
        rpy="0 0 0" />
      <geometry>
        <mesh
          filename="package://magbot_gazebo/description/meshes/base_collision.STL" />
      </geometry>
    </collision>
  </link>

  <!--LIDAR-->
  <link name="lidar_link">
    <inertial>
      <origin xyz="0 0 0" rpy="0 0 0"/>
      <mass value="0.1"/> <!-- Adjust mass as needed -->
      <inertia
        ixx="0.0001" ixy="0.0" ixz="0.0"
        iyy="0.0001" iyz="0.0"
        izz="0.0001"/>
    </inertial>

    <visual>
      <origin xyz="0 0 0" rpy="0 0 0"/>
      <geometry>
        <cylinder length="0.05" radius="0.05"/> <!-- Adjust dimensions as needed -->
      </geometry>
      <material name="blue">
        <color rgba="0 0 1 1"/> <!-- Blue color for visualization -->
      </material>
    </visual>

    <collision>
      <origin xyz="0 0 0" rpy="0 0 0"/>
      <geometry>
        <cylinder length="0.05" radius="0.05"/> <!-- Adjust dimensions as needed -->
      </geometry>
    </collision>
  </link>

  <joint name="lidar_joint" type="fixed">
    <parent link="base_link"/>
    <child link="lidar_link"/>
    <origin xyz="0 0 0.05" rpy="0 0 0"/> <!-- Adjust xyz to place the LiDAR on top of the base_link -->
  </joint>

  <gazebo reference="lidar_link">
    <sensor type="ray" name="lidar_sensor">
      <pose>0 0 0 0 0 0</pose>
      <visualize>true</visualize>
      <update_rate>10</update_rate>
      <ray>
        <scan>
          <horizontal>
            <samples>360</samples>
            <resolution>1.0</resolution>
            <min_angle>-3.14159</min_angle> <!-- -180 degrees -->
            <max_angle>3.14159</max_angle>  <!-- +180 degrees -->
          </horizontal>
        </scan>
        <range>
          <min>0.1</min>
          <max>10.0</max>
          <resolution>0.01</resolution>
        </range>
        <noise>
          <type>gaussian</type>
          <mean>0.0</mean>
          <stddev>0.01</stddev>
        </noise>
      </ray>
      <plugin name="gazebo_ros_lidar_controller" filename="libgazebo_ros_ray_sensor.so">
        <ros>
          <namespace>/</namespace>
          <remapping>~/out:=scan</remapping>
        </ros>
        <output_type>sensor_msgs/LaserScan</output_type>
        <frame_name>lidar_link</frame_name>
      </plugin>
    </sensor>
  </gazebo>
  <!-- FL_link1 -->
  <link
    name="FL_link1">
    <inertial>
      <origin xyz="0 0 0" />
      <mass value="0.30000000" />
      <inertia ixx="0.00019300" ixy="0.00000000" ixz="0.00000000" iyy="0.00014890" iyz="0.00000000"
        izz="0.00012410" />
    </inertial>
    <visual>
      <origin
        xyz="0 0 0"
        rpy="0 0 0" />
      <geometry>
        <mesh
          filename="package://magbot_gazebo/description/meshes/FL_link1.dae" />
      </geometry>
      <material
        name="">
        <color
          rgba="0.79216 0.81961 0.93333 1" />
      </material>
    </visual>
    <collision>
      <origin
        xyz="0 0 0"
        rpy="0 0 0" />
      <geometry>
        <mesh
          filename="package://magbot_gazebo/description/meshes/L_link1_collision.STL" />
      </geometry>
    </collision>
  </link>

  <!-- FL_link2 -->
  <link
    name="FL_link2">
    <inertial>
      <origin xyz="0 0 0" />
      <mass value="0.10000000" />
      <inertia ixx="0.00000700" ixy="0.00000000" ixz="0.00000444" iyy="0.00017260" iyz="0.00000000"
        izz="0.00017568" />
    </inertial>

    <visual>
      <origin
        xyz="0 0 0"
        rpy="0 0 0" />
      <geometry>
        <mesh
          filename="package://magbot_gazebo/description/meshes/L_link2.dae" />
      </geometry>
      <material
        name="">
        <color
          rgba="0.79216 0.81961 0.93333 1" />
      </material>
    </visual>
    <collision>
      <origin
        xyz="0 0 0"
        rpy="0 0 0" />
      <geometry>
        <mesh
          filename="package://magbot_gazebo/description/meshes/L_link2_collision.STL" />
      </geometry>
    </collision>
  </link>

  <!-- FL_link3 -->
  <link
    name="FL_link3">
    <inertial>
      <origin xyz="0 0 0" />
      <mass value="0.10000000" />
      <inertia ixx="0.00000936" ixy="-0.00001360" ixz="-0.00000319" iyy="0.00019747"
        iyz="-0.00000027" izz="0.00019702" />
    </inertial>

    <visual>
      <origin
        xyz="0 0 0"
        rpy="0 0 0" />
      <geometry>
        <mesh
          filename="package://magbot_gazebo/description/meshes/L_link3.dae" />
      </geometry>
      <material
        name="">
        <color
          rgba="0.79216 0.81961 0.93333 1" />
      </material>
    </visual>
    <collision>
      <origin
        xyz="0 0 0"
        rpy="0 0 0" />
      <geometry>
        <mesh
          filename="package://magbot_gazebo/description/meshes/L_link3_collision.STL" />
      </geometry>
    </collision>
  </link>

  <!-- FL_link4 -->
  <link
    name="FL_link4">
    <inertial>
      <origin xyz="0 0 0" />
      <mass value="0.02000000" />
      <inertia ixx="0.00000060" ixy="-0.00000013" ixz="0.00000000" iyy="0.00000058" iyz="0.00000000"
        izz="0.00000045" />
    </inertial>

    <visual>
      <origin
        xyz="0 0 0"
        rpy="0 0 0" />
      <geometry>
        <mesh
          filename="package://magbot_gazebo/description/meshes/link4.dae" />
      </geometry>
      <material
        name="">
        <color
          rgba="0.79216 0.81961 0.93333 1" />
      </material>
    </visual>
    <collision>
      <origin
        xyz="0 0 0"
        rpy="0 0 0" />
      <geometry>
        <mesh
          filename="package://magbot_gazebo/description/meshes/link4_collision.STL" />
      </geometry>
    </collision>
  </link>

  <!-- FR_link1 -->
  <link
    name="FR_link1">
    <inertial>
      <origin xyz="0 0 0" />
      <mass value="0.30000000" />
      <inertia ixx="0.00019300" ixy="0.00000000" ixz="0.00000000" iyy="0.00014890" iyz="0.00000000"
        izz="0.00012410" />
    </inertial>

    <visual>
      <origin
        xyz="0 0 0"
        rpy="0 0 0" />
      <geometry>
        <mesh
          filename="package://magbot_gazebo/description/meshes/FR_link1.dae" />
      </geometry>
      <material
        name="">
        <color
          rgba="0.79216 0.81961 0.93333 1" />
      </material>
    </visual>
    <collision>
      <origin
        xyz="0 0 0"
        rpy="0 0 0" />
      <geometry>
        <mesh
          filename="package://magbot_gazebo/description/meshes/R_link1_collision.STL" />
      </geometry>
    </collision>
  </link>

  <!-- FR_link2 -->
  <link
    name="FR_link2">
    <inertial>
      <origin xyz="0 0 0" />
      <mass value="0.10000000" />
      <inertia ixx="0.00000700" ixy="0.00000000" ixz="0.00000444" iyy="0.00017260" iyz="0.00000000"
        izz="0.00017568" />
    </inertial>

    <visual>
      <origin
        xyz="0 0 0"
        rpy="0 0 0" />
      <geometry>
        <mesh
          filename="package://magbot_gazebo/description/meshes/R_link2.dae" />
      </geometry>
      <material
        name="">
        <color
          rgba="0.79216 0.81961 0.93333 1" />
      </material>
    </visual>
    <collision>
      <origin
        xyz="0 0 0"
        rpy="0 0 0" />
      <geometry>
        <mesh
          filename="package://magbot_gazebo/description/meshes/R_link2_collision.STL" />
      </geometry>
    </collision>
  </link>

  <!-- FR_link3 -->
  <link
    name="FR_link3">
    <inertial>
      <origin xyz="0 0 0" />
      <mass value="0.10000000" />
      <inertia ixx="0.00000936" ixy="-0.00001360" ixz="-0.00000319" iyy="0.00019747"
        iyz="-0.00000027" izz="0.00019702" />
    </inertial>

    <visual>
      <origin
        xyz="0 0 0"
        rpy="0 0 0" />
      <geometry>
        <mesh
          filename="package://magbot_gazebo/description/meshes/R_link3.dae" />
      </geometry>
      <material
        name="">
        <color
          rgba="0.79216 0.81961 0.93333 1" />
      </material>
    </visual>
    <collision>
      <origin
        xyz="0 0 0"
        rpy="0 0 0" />
      <geometry>
        <mesh
          filename="package://magbot_gazebo/description/meshes/R_link3_collision.STL" />
      </geometry>
    </collision>
  </link>

  <!-- FR_link4 -->
  <link
    name="FR_link4">
    <inertial>
      <origin xyz="0 0 0" />
      <mass value="0.02000000" />
      <inertia ixx="0.00000060" ixy="-0.00000013" ixz="0.00000000" iyy="0.00000058" iyz="0.00000000"
        izz="0.00000045" />
    </inertial>

    <visual>
      <origin
        xyz="0 0 0"
        rpy="0 0 0" />
      <geometry>
        <mesh
          filename="package://magbot_gazebo/description/meshes/link4.dae" />
      </geometry>
      <material
        name="">
        <color
          rgba="0.79216 0.81961 0.93333 1" />
      </material>
    </visual>
    <collision>
      <origin
        xyz="0 0 0"
        rpy="0 0 0" />
      <geometry>
        <mesh
          filename="package://magbot_gazebo/description/meshes/link4_collision.STL" />
      </geometry>
    </collision>
  </link>

  <!-- RL_link1 -->
  <link
    name="RL_link1">
    <inertial>
      <origin xyz="0 0 0" />
      <mass value="0.30000000" />
      <inertia ixx="0.00019300" ixy="0.00000000" ixz="0.00000000" iyy="0.00014890" iyz="0.00000000"
        izz="0.00012410" />
    </inertial>

    <visual>
      <origin
        xyz="0 0 0"
        rpy="0 0 0" />
      <geometry>
        <mesh
          filename="package://magbot_gazebo/description/meshes/RL_link1.dae" />
      </geometry>
      <material
        name="">
        <color
          rgba="0.79216 0.81961 0.93333 1" />
      </material>
    </visual>
    <collision>
      <origin
        xyz="0 0 0"
        rpy="0 0 0" />
      <geometry>
        <mesh
          filename="package://magbot_gazebo/description/meshes/L_link1_collision.STL" />
      </geometry>
    </collision>
  </link>

  <!-- RL_link2 -->
  <link
    name="RL_link2">
    <inertial>
      <origin xyz="0 0 0" />
      <mass value="0.10000000" />
      <inertia ixx="0.00000700" ixy="0.00000000" ixz="0.00000444" iyy="0.00017260" iyz="0.00000000"
        izz="0.00017568" />
    </inertial>

    <visual>
      <origin
        xyz="0 0 0"
        rpy="0 0 0" />
      <geometry>
        <mesh
          filename="package://magbot_gazebo/description/meshes/L_link2.dae" />
      </geometry>
      <material
        name="">
        <color
          rgba="0.79216 0.81961 0.93333 1" />
      </material>
    </visual>
    <collision>
      <origin
        xyz="0 0 0"
        rpy="0 0 0" />
      <geometry>
        <mesh
          filename="package://magbot_gazebo/description/meshes/L_link2_collision.STL" />
      </geometry>
    </collision>
  </link>

  <!-- RL_link3 -->
  <link
    name="RL_link3">
    <inertial>
      <origin xyz="0 0 0" />
      <mass value="0.10000000" />
      <inertia ixx="0.00000936" ixy="-0.00001360" ixz="-0.00000319" iyy="0.00019747"
        iyz="-0.00000027" izz="0.00019702" />
    </inertial>

    <visual>
      <origin
        xyz="0 0 0"
        rpy="0 0 0" />
      <geometry>
        <mesh
          filename="package://magbot_gazebo/description/meshes/L_link3.dae" />
      </geometry>
      <material
        name="">
        <color
          rgba="0.79216 0.81961 0.93333 1" />
      </material>
    </visual>
    <collision>
      <origin
        xyz="0 0 0"
        rpy="0 0 0" />
      <geometry>
        <mesh
          filename="package://magbot_gazebo/description/meshes/L_link3_collision.STL" />
      </geometry>
    </collision>
  </link>

  <!-- RL_link4 -->
  <link
    name="RL_link4">
    <inertial>
      <origin xyz="0 0 0" />
      <mass value="0.02000000" />
      <inertia ixx="0.00000060" ixy="-0.00000013" ixz="0.00000000" iyy="0.00000058" iyz="0.00000000"
        izz="0.00000045" />
    </inertial>

    <visual>
      <origin
        xyz="0 0 0"
        rpy="0 0 0" />
      <geometry>
        <mesh
          filename="package://magbot_gazebo/description/meshes/link4.dae" />
      </geometry>
      <material
        name="">
        <color
          rgba="0.79216 0.81961 0.93333 1" />
      </material>
    </visual>
    <collision>
      <origin
        xyz="0 0 0"
        rpy="0 0 0" />
      <geometry>
        <mesh
          filename="package://magbot_gazebo/description/meshes/link4_collision.STL" />
      </geometry>
    </collision>
  </link>

  <!-- RR_link1 -->
  <link
    name="RR_link1">
    <inertial>
      <origin xyz="0 0 0" />
      <mass value="0.30000000" />
      <inertia ixx="0.00019300" ixy="0.00000000" ixz="0.00000000" iyy="0.00014890" iyz="0.00000000"
        izz="0.00012410" />
    </inertial>

    <visual>
      <origin
        xyz="0 0 0"
        rpy="0 0 0" />
      <geometry>
        <mesh
          filename="package://magbot_gazebo/description/meshes/RR_link1.dae" />
      </geometry>
      <material
        name="">
        <color
          rgba="0.79216 0.81961 0.93333 1" />
      </material>
    </visual>
    <collision>
      <origin
        xyz="0 0 0"
        rpy="0 0 0" />
      <geometry>
        <mesh
          filename="package://magbot_gazebo/description/meshes/R_link1_collision.STL" />
      </geometry>
    </collision>
  </link>

  <!-- RR_link2 -->
  <link
    name="RR_link2">
    <inertial>
      <origin xyz="0 0 0" />
      <mass value="0.10000000" />
      <inertia ixx="0.00000700" ixy="0.00000000" ixz="0.00000444" iyy="0.00017260" iyz="0.00000000"
        izz="0.00017568" />
    </inertial>

    <visual>
      <origin
        xyz="0 0 0"
        rpy="0 0 0" />
      <geometry>
        <mesh
          filename="package://magbot_gazebo/description/meshes/R_link2.dae" />
      </geometry>
      <material
        name="">
        <color
          rgba="0.79216 0.81961 0.93333 1" />
      </material>
    </visual>
    <collision>
      <origin
        xyz="0 0 0"
        rpy="0 0 0" />
      <geometry>
        <mesh
          filename="package://magbot_gazebo/description/meshes/R_link2_collision.STL" />
      </geometry>
    </collision>
  </link>

  <!-- RR_link3 -->
  <link
    name="RR_link3">
    <inertial>
      <origin xyz="0 0 0" />
      <mass value="0.10000000" />
      <inertia ixx="0.00000936" ixy="-0.00001360" ixz="-0.00000319" iyy="0.00019747"
        iyz="-0.00000027" izz="0.00019702" />
    </inertial>

    <visual>
      <origin
        xyz="0 0 0"
        rpy="0 0 0" />
      <geometry>
        <mesh
          filename="package://magbot_gazebo/description/meshes/R_link3.dae" />
      </geometry>
      <material
        name="">
        <color
          rgba="0.79216 0.81961 0.93333 1" />
      </material>
    </visual>
    <collision>
      <origin
        xyz="0 0 0"
        rpy="0 0 0" />
      <geometry>
        <mesh
          filename="package://magbot_gazebo/description/meshes/R_link3_collision.STL" />
      </geometry>
    </collision>
  </link>

  <!-- RR_link4 -->
  <link
    name="RR_link4">
    <inertial>
      <origin xyz="0 0 0" />
      <mass value="0.02000000" />
      <inertia ixx="0.00000060" ixy="-0.00000013" ixz="0.00000000" iyy="0.00000058" iyz="0.00000000"
        izz="0.00000045" />
    </inertial>

    <visual>
      <origin
        xyz="0 0 0"
        rpy="0 0 0" />
      <geometry>
        <mesh
          filename="package://magbot_gazebo/description/meshes/link4.dae" />
      </geometry>
      <material
        name="">
        <color
          rgba="0.79216 0.81961 0.93333 1" />
      </material>
    </visual>
    <collision>
      <origin
        xyz="0 0 0"
        rpy="0 0 0" />
      <geometry>
        <mesh
          filename="package://magbot_gazebo/description/meshes/link4_collision.STL" />
      </geometry>
    </collision>
  </link>


  <!-- JOINTS -->

  <joint
    name="FL_theta1"
    type="revolute">
    <origin
      xyz="0.11165 0.061 -0.0144"
      rpy="1.5708 0 1.5708" />
    <parent
      link="base_link" />
    <child
      link="FL_link1" />
    <axis
      xyz="0 0 1" />
    <limit
      lower="-0.785398"
      upper="0.785398"
      effort="${effort_limit}"
      velocity="3" />
    <dynamics damping="0.1" friction="0.1" />
  </joint>
  <joint
    name="FL_theta2"
    type="revolute">
    <origin
      xyz="0.0496000007984339 0.014400000013256 0"
      rpy="1.57079634307336 1.57079568414183 -1.57079631051644" />
    <parent
      link="FL_link1" />
    <child
      link="FL_link2" />
    <axis
      xyz="0 0 1" />
    <limit
      lower="-3"
      upper="3"
      effort="${effort_limit}"
      velocity="3" />
    <dynamics damping="0.1" friction="0.1" />
  </joint>
  <joint
    name="FL_theta3"
    type="revolute">
    <origin
      xyz="0.129999999999897 0 0"
      rpy="0 0 1.57079594774422" />
    <parent
      link="FL_link2" />
    <child
      link="FL_link3" />
    <axis
      xyz="0 0 1" />
    <limit
      lower="-3"
      upper="3"
      effort="${effort_limit}"
      velocity="3" />
    <dynamics damping="0.1" friction="0.1" />
  </joint>
  <joint
    name="FL_foot"
    type="fixed">
    <origin
      xyz="0.138136646352288 0 0"
      rpy="0 0 0" />
    <parent
      link="FL_link3" />
    <child
      link="FL_link4" />
    <axis
      xyz="0 0 0" />
  </joint>


  <joint
    name="FR_theta1"
    type="revolute">
    <origin
      xyz="0.111650000000002 -0.0609999999999988 -0.0144000000000242"
      rpy="1.57079632679492 0 1.5707963267949" />
    <parent
      link="base_link" />
    <child
      link="FR_link1" />
    <axis
      xyz="0 0 -1" />
    <limit
      lower="-0.785398"
      upper="0.785398"
      effort="${effort_limit}"
      velocity="3" />
    <dynamics damping="0.1" friction="0.1" />
  </joint>
  <joint
    name="FR_theta2"
    type="revolute">
    <origin
      xyz="-0.0495999992169121 0.0144000000000242 0"
      rpy="1.57079632309575 1.57079572077363 -1.57079633049404" />
    <parent
      link="FR_link1" />
    <child
      link="FR_link2" />
    <axis
      xyz="0 0 1" />
    <limit
      lower="-3"
      upper="3"
      effort="${effort_limit}"
      velocity="3" />
    <dynamics damping="0.1" friction="0.1" />
  </joint>
  <joint
    name="FR_theta3"
    type="revolute">
    <origin
      xyz="0.13000000353672 0 0"
      rpy="0 0 1.57079598438978" />
    <parent
      link="FR_link2" />
    <child
      link="FR_link3" />
    <axis
      xyz="0 0 1" />
    <limit
      lower="-3"
      upper="3"
      effort="${effort_limit}"
      velocity="3" />
    <dynamics damping="0.1" friction="0.1" />
  </joint>
  <joint
    name="FR_foot"
    type="fixed">
    <origin
      xyz="0.13813664635243 0 0"
      rpy="0 0 0" />
    <parent
      link="FR_link3" />
    <child
      link="FR_link4" />
    <axis
      xyz="0 0 0" />
  </joint>


  <joint
    name="RL_theta1"
    type="revolute">
    <origin
      xyz="-0.11165 0.061 -0.0144"
      rpy="1.5708 0 1.5708" />
    <parent
      link="base_link" />
    <child
      link="RL_link1" />
    <axis
      xyz="0 0 1" />
    <limit
      lower="-0.785398"
      upper="0.785398"
      effort="${effort_limit}"
      velocity="3" />
    <dynamics damping="0.1" friction="0.1" />
  </joint>
  <joint
    name="RL_theta2"
    type="revolute">
    <origin
      xyz="0.0496000007984574 0.014399999996394 0"
      rpy="1.5707963301177 1.57079568414183 -1.57079632347209" />
    <parent
      link="RL_link1" />
    <child
      link="RL_link2" />
    <axis
      xyz="0 0 1" />
    <limit
      lower="-3"
      upper="3"
      effort="${effort_limit}"
      velocity="3" />
    <dynamics damping="0.1" friction="0.1" />
  </joint>
  <joint
    name="RL_theta3"
    type="revolute">
    <origin
      xyz="0.129999999994849 0 0"
      rpy="0 0 1.57079594787326" />
    <parent
      link="RL_link2" />
    <child
      link="RL_link3" />
    <axis
      xyz="0 0 0.999999999999979" />
    <limit
      lower="-3"
      upper="3"
      effort="${effort_limit}"
      velocity="3" />
    <dynamics damping="0.1" friction="0.1" />
  </joint>
  <joint
    name="RL_foot"
    type="fixed">
    <origin
      xyz="0.138136646352323 0 0"
      rpy="0 0 0" />
    <parent
      link="RL_link3" />
    <child
      link="RL_link4" />
    <axis
      xyz="0 0 0" />
  </joint>


  <joint
    name="RR_theta1"
    type="revolute">
    <origin
      xyz="-0.111650000000003 -0.0609999999999995 -0.0144000000000178"
      rpy="1.57079632679492 0 1.5707963267949" />
    <parent
      link="base_link" />
    <child
      link="RR_link1" />
    <axis
      xyz="0 0 -1" />
    <limit
      lower="-0.785398"
      upper="0.785398"
      effort="${effort_limit}"
      velocity="3" />
    <dynamics damping="0.1" friction="0.1" />
  </joint>
  <joint
    name="RR_theta2"
    type="revolute">
    <origin
      xyz="-0.0495999992169147 0.0144000000000178 0"
      rpy="1.57079631992506 1.57079572077363 -1.57079633366473" />
    <parent
      link="RR_link1" />
    <child
      link="RR_link2" />
    <axis
      xyz="0 0 1" />
    <limit
      lower="-3"
      upper="3"
      effort="${effort_limit}"
      velocity="3" />
    <dynamics damping="0.1" friction="0.1" />
  </joint>
  <joint
    name="RR_theta3"
    type="revolute">
    <origin
      xyz="0.13000000353672 0 0"
      rpy="0 0 1.57079598438978" />
    <parent
      link="RR_link2" />
    <child
      link="RR_link3" />
    <axis
      xyz="0 0 0.999999999999998" />
    <limit
      lower="-3"
      upper="3"
      effort="${effort_limit}"
      velocity="3" />
    <dynamics damping="0.1" friction="0.1" />
  </joint>
  <joint
    name="RR_foot"
    type="fixed">
    <origin
      xyz="0.138136646352431 0 0"
      rpy="0 0 0" />
    <parent
      link="RR_link3" />
    <child
      link="RR_link4" />
    <axis
      xyz="0 0 0" />
  </joint>


  <!-- ROS2 control plugin -->
  <gazebo>
    <plugin name="gazebo_ros2_control" filename="libgazebo_ros2_control.so">
      <parameters>$(find magbot_gazebo)/config/dingo_controllers.yaml</parameters>
      <ros>
        <namespace>/</namespace>
        <remapping>~/out:=/magbot/joint_states</remapping>
      </ros>
    </plugin>

    <physics type="ode">
      <ode>
        <solver>
          <type>quick</type>
          <iters>50</iters>
          <sor>1.3</sor>
        </solver>
        <constraints>
          <cfm>0.0001</cfm>
          <erp>0.2</erp>
          <contact_max_correcting_vel>100.0</contact_max_correcting_vel>
          <contact_surface_layer>0.001</contact_surface_layer>
        </constraints>
      </ode>
      <max_step_size>0.001</max_step_size>
      <real_time_factor>1</real_time_factor>
      <real_time_update_rate>1000</real_time_update_rate>
      <gravity>0 0 -9.81</gravity>
    </physics>
  </gazebo>

  <gazebo reference="base_link">
    <gravity>true</gravity>
    <sensor name="imu_sensor" type="imu">
      <always_on>true</always_on>
      <update_rate>100</update_rate>
      <visualize>true</visualize>
      <imu>
        <angular_velocity>
          <x>
            <noise type="gaussian">
              <mean>0.0</mean>
              <stddev>0.01</stddev>
            </noise>
          </x>
          <y>
            <noise type="gaussian">
              <mean>0.0</mean>
              <stddev>0.01</stddev>
            </noise>
          </y>
          <z>
            <noise type="gaussian">
              <mean>0.0</mean>
              <stddev>0.01</stddev>
            </noise>
          </z>
        </angular_velocity>
        <linear_acceleration>
          <x>
            <noise type="gaussian">
              <mean>0.0</mean>
              <stddev>0.1</stddev>
            </noise>
          </x>
          <y>
            <noise type="gaussian">
              <mean>0.0</mean>
              <stddev>0.1</stddev>
            </noise>
          </y>
          <z>
            <noise type="gaussian">
              <mean>0.0</mean>
              <stddev>0.1</stddev>
            </noise>
          </z>
        </linear_acceleration>
      </imu>
      <plugin name="imu_plugin" filename="libgazebo_ros_imu_sensor.so">
        <ros>
          <namespace>/magbot</namespace>
          <remapping>~/out:=imu</remapping>
        </ros>
        <initial_orientation_as_reference>false</initial_orientation_as_reference>
        <frame_name>base_link</frame_name>
      </plugin>
    </sensor>
  </gazebo>

  <!-- FR4 friction -->
  <gazebo reference="FR_link4">
    <mu1>1.0</mu1>
    <mu2>1.0</mu2>
    <min_depth>0.0002</min_depth> <!-- Updated to min_depth to match Gazebo naming -->
    <kp>1000000.0</kp>            <!-- Removed value attribute for ROS2 syntax -->
    <kd>100.0</kd>                <!-- Removed value attribute for ROS2 syntax -->
  </gazebo>

  <!-- FL4 friction -->
  <gazebo reference="FL_link4">
    <mu1>1.0</mu1>
    <mu2>1.0</mu2>
    <min_depth>0.0002</min_depth>
    <kp>1000000.0</kp>
    <kd>100.0</kd>
  </gazebo>

  <!-- RR4 friction -->
  <gazebo reference="RR_link4">
    <mu1>1.0</mu1>
    <mu2>1.0</mu2>
    <min_depth>0.0002</min_depth>
    <kp>1000000.0</kp>
    <kd>100.0</kd>
  </gazebo>

  <!-- RL4 friction -->
  <gazebo reference="RL_link4">
    <mu1>1.0</mu1>
    <mu2>1.0</mu2>
    <min_depth>0.0002</min_depth>
    <kp>1000000.0</kp>
    <kd>100.0</kd>
  </gazebo>

  <xacro:dingo_ros2_control name="DingoRobotSystem" />

  <gazebo reference="base_link">
    <selfCollide>true</selfCollide>
    <mu1>0.2</mu1>
    <mu2>0.2</mu2>
    <kp>100000.0</kp>
    <kd>10.0</kd>
  </gazebo>

</robot>
