<sdf version='1.7'>
  <model name='dingo'>
    <link name='base_link'>
      <inertial>
        <pose>-0.026793 -0.000121 0.004572 0 -0 0</pose>
        <mass>5</mass>
        <inertia>
          <ixx>0.0073276</ixx>
          <ixy>0</ixy>
          <ixz>0.0002194</ixz>
          <iyy>0.029958</iyy>
          <iyz>-2e-08</iyz>
          <izz>0.03298</izz>
        </inertia>
      </inertial>
      <collision name='base_link_collision'>
        <pose>0 0 0 0 -0 0</pose>
        <geometry>
          <mesh>
            <scale>1 1 1</scale>
            <uri>model://magbot_gazebo/description/meshes/base_collision.STL</uri>
          </mesh>
        </geometry>
        <surface>
          <contact>
            <ode/>
          </contact>
          <friction>
            <ode/>
          </friction>
        </surface>
      </collision>
      <visual name='base_link_visual'>
        <pose>0 0 0 0 -0 0</pose>
        <geometry>
          <mesh>
            <scale>1 1 1</scale>
            <uri>model://magbot_gazebo/description/meshes/base_link.dae</uri>
          </mesh>
        </geometry>
      </visual>
      <gravity>1</gravity>
      <sensor name='imu_sensor' type='imu'>
        <always_on>1</always_on>
        <update_rate>100</update_rate>
        <visualize>1</visualize>
        <topic>__default_topic__</topic>
        <imu>
          <angular_velocity>
            <noise>
              <type>gaussian</type>
              <mean>0.0</mean>
              <stddev>0.01</stddev>
            </noise>
          </angular_velocity>
          <linear_acceleration>
            <noise>
              <type>gaussian</type>
              <mean>0.0</mean>
              <stddev>0.1</stddev>
            </noise>
          </linear_acceleration>
        </imu>
        <pose>0 0 0 0 -0 0</pose>
        <plugin name='imu_plugin' filename='libgazebo_ros_imu_sensor.so'>
          <ros>
            <namespace>/dingo</namespace>
            <remapping>~/out:=imu</remapping>
          </ros>
          <topicName>imu</topicName>
          <bodyName>base_link</bodyName>
          <updateRateHZ>15.0</updateRateHZ>
          <xyzOffset>0 0 0</xyzOffset>
          <rpyOffset>0 0 0</rpyOffset>
          <frameName>base_link</frameName>
        </plugin>
      </sensor>
    </link>
    <joint name='FL_theta1' type='revolute'>
      <pose relative_to='base_link'>0.11165 0.061 -0.0144 1.5708 -0 1.5708</pose>
      <parent>base_link</parent>
      <child>FL_link1</child>
      <axis>
        <xyz>0 0 1</xyz>
        <limit>
          <lower>-0.785398</lower>
          <upper>0.785398</upper>
          <effort>10</effort>
          <velocity>3</velocity>
        </limit>
        <dynamics>
          <damping>1000</damping>
          <friction>1000</friction>
          <spring_reference>0</spring_reference>
          <spring_stiffness>0</spring_stiffness>
        </dynamics>
      </axis>
    </joint>
    <link name='FL_link1'>
      <pose relative_to='FL_theta1'>0 0 0 0 -0 0</pose>
      <inertial>
        <pose>0 0 0 0 -0 0</pose>
        <mass>0.3</mass>
        <inertia>
          <ixx>0.000193</ixx>
          <ixy>0</ixy>
          <ixz>0</ixz>
          <iyy>0.0001489</iyy>
          <iyz>0</iyz>
          <izz>0.0001241</izz>
        </inertia>
      </inertial>
      <collision name='FL_link1_collision'>
        <pose>0 0 0 0 -0 0</pose>
        <geometry>
          <mesh>
            <scale>1 1 1</scale>
            <uri>model://magbot_gazebo/description/meshes/L_link1_collision.STL</uri>
          </mesh>
        </geometry>
      </collision>
      <visual name='FL_link1_visual'>
        <pose>0 0 0 0 -0 0</pose>
        <geometry>
          <mesh>
            <scale>1 1 1</scale>
            <uri>model://magbot_gazebo/description/meshes/FL_link1.dae</uri>
          </mesh>
        </geometry>
      </visual>
    </link>
    <joint name='FL_theta2' type='revolute'>
      <pose relative_to='FL_link1'>0.0496 0.0144 0 1.5708 1.5708 -1.5708</pose>
      <parent>FL_link1</parent>
      <child>FL_link2</child>
      <axis>
        <xyz>0 0 1</xyz>
        <limit>
          <lower>-3</lower>
          <upper>3</upper>
          <effort>10</effort>
          <velocity>3</velocity>
        </limit>
        <dynamics>
          <damping>1000</damping>
          <friction>1000</friction>
          <spring_reference>0</spring_reference>
          <spring_stiffness>0</spring_stiffness>
        </dynamics>
      </axis>
    </joint>
    <link name='FL_link2'>
      <pose relative_to='FL_theta2'>0 0 0 0 -0 0</pose>
      <inertial>
        <pose>0 0 0 0 -0 0</pose>
        <mass>0.1</mass>
        <inertia>
          <ixx>7e-06</ixx>
          <ixy>0</ixy>
          <ixz>4.44e-06</ixz>
          <iyy>0.0001726</iyy>
          <iyz>0</iyz>
          <izz>0.00017568</izz>
        </inertia>
      </inertial>
      <collision name='FL_link2_collision'>
        <pose>0 0 0 0 -0 0</pose>
        <geometry>
          <mesh>
            <scale>1 1 1</scale>
            <uri>model://magbot_gazebo/description/meshes/L_link2_collision.STL</uri>
          </mesh>
        </geometry>
      </collision>
      <visual name='FL_link2_visual'>
        <pose>0 0 0 0 -0 0</pose>
        <geometry>
          <mesh>
            <scale>1 1 1</scale>
            <uri>model://magbot_gazebo/description/meshes/L_link2.dae</uri>
          </mesh>
        </geometry>
      </visual>
    </link>
    <joint name='FL_theta3' type='revolute'>
      <pose relative_to='FL_link2'>0.13 0 0 0 -0 1.5708</pose>
      <parent>FL_link2</parent>
      <child>FL_link3</child>
      <axis>
        <xyz>0 0 1</xyz>
        <limit>
          <lower>-3</lower>
          <upper>3</upper>
          <effort>10</effort>
          <velocity>3</velocity>
        </limit>
        <dynamics>
          <damping>1000</damping>
          <friction>1000</friction>
          <spring_reference>0</spring_reference>
          <spring_stiffness>0</spring_stiffness>
        </dynamics>
      </axis>
    </joint>
    <link name='FL_link3'>
      <pose relative_to='FL_theta3'>0 0 0 0 -0 0</pose>
      <inertial>
        <pose>0.023023 0 0 0 -0 0</pose>
        <mass>0.12</mass>
        <inertia>
          <ixx>9.96e-06</ixx>
          <ixy>-1.373e-05</ixy>
          <ixz>-3.19e-06</ixz>
          <iyy>0.000516079</iyy>
          <iyz>-2.7e-07</iyz>
          <izz>0.000515499</izz>
        </inertia>
      </inertial>
      <collision name='FL_link3_collision'>
        <pose>0 0 0 0 -0 0</pose>
        <geometry>
          <mesh>
            <scale>1 1 1</scale>
            <uri>model://magbot_gazebo/description/meshes/L_link3_collision.STL</uri>
          </mesh>
        </geometry>
      </collision>
      <collision name='FL_link3_fixed_joint_lump__FL_link4_collision_1'>
        <pose>0.138137 0 0 0 -0 0</pose>
        <geometry>
          <mesh>
            <scale>1 1 1</scale>
            <uri>model://magbot_gazebo/description/meshes/link4_collision.STL</uri>
          </mesh>
        </geometry>
        <surface>
          <contact>
            <ode>
              <kp>1e+06</kp>
              <kd>100</kd>
            </ode>
          </contact>
          <friction>
            <ode>
              <mu>1</mu>
              <mu2>1</mu2>
            </ode>
          </friction>
        </surface>
      </collision>
      <visual name='FL_link3_visual'>
        <pose>0 0 0 0 -0 0</pose>
        <geometry>
          <mesh>
            <scale>1 1 1</scale>
            <uri>model://magbot_gazebo/description/meshes/L_link3.dae</uri>
          </mesh>
        </geometry>
      </visual>
      <visual name='FL_link3_fixed_joint_lump__FL_link4_visual_1'>
        <pose>0.138137 0 0 0 -0 0</pose>
        <geometry>
          <mesh>
            <scale>1 1 1</scale>
            <uri>model://magbot_gazebo/description/meshes/link4.dae</uri>
          </mesh>
        </geometry>
      </visual>
      <min_depth>0.0002</min_depth>
    </link>
    <joint name='FR_theta1' type='revolute'>
      <pose relative_to='base_link'>0.11165 -0.061 -0.0144 1.5708 0 1.5708</pose>
      <parent>base_link</parent>
      <child>FR_link1</child>
      <axis>
        <xyz>0 0 -1</xyz>
        <limit>
          <lower>-0.785398</lower>
          <upper>0.785398</upper>
          <effort>10</effort>
          <velocity>3</velocity>
        </limit>
        <dynamics>
          <damping>1000</damping>
          <friction>1000</friction>
          <spring_reference>0</spring_reference>
          <spring_stiffness>0</spring_stiffness>
        </dynamics>
      </axis>
    </joint>
    <link name='FR_link1'>
      <pose relative_to='FR_theta1'>0 0 0 0 -0 0</pose>
      <inertial>
        <pose>0 0 0 0 -0 0</pose>
        <mass>0.3</mass>
        <inertia>
          <ixx>0.000193</ixx>
          <ixy>0</ixy>
          <ixz>0</ixz>
          <iyy>0.0001489</iyy>
          <iyz>0</iyz>
          <izz>0.0001241</izz>
        </inertia>
      </inertial>
      <collision name='FR_link1_collision'>
        <pose>0 0 0 0 -0 0</pose>
        <geometry>
          <mesh>
            <scale>1 1 1</scale>
            <uri>model://magbot_gazebo/description/meshes/R_link1_collision.STL</uri>
          </mesh>
        </geometry>
      </collision>
      <visual name='FR_link1_visual'>
        <pose>0 0 0 0 -0 0</pose>
        <geometry>
          <mesh>
            <scale>1 1 1</scale>
            <uri>model://magbot_gazebo/description/meshes/FR_link1.dae</uri>
          </mesh>
        </geometry>
      </visual>
    </link>
    <joint name='FR_theta2' type='revolute'>
      <pose relative_to='FR_link1'>-0.0496 0.0144 0 1.5708 1.5708 -1.5708</pose>
      <parent>FR_link1</parent>
      <child>FR_link2</child>
      <axis>
        <xyz>0 0 1</xyz>
        <limit>
          <lower>-3</lower>
          <upper>3</upper>
          <effort>10</effort>
          <velocity>3</velocity>
        </limit>
        <dynamics>
          <damping>1000</damping>
          <friction>1000</friction>
          <spring_reference>0</spring_reference>
          <spring_stiffness>0</spring_stiffness>
        </dynamics>
      </axis>
    </joint>
    <link name='FR_link2'>
      <pose relative_to='FR_theta2'>0 0 0 0 -0 0</pose>
      <inertial>
        <pose>0 0 0 0 -0 0</pose>
        <mass>0.1</mass>
        <inertia>
          <ixx>7e-06</ixx>
          <ixy>0</ixy>
          <ixz>4.44e-06</ixz>
          <iyy>0.0001726</iyy>
          <iyz>0</iyz>
          <izz>0.00017568</izz>
        </inertia>
      </inertial>
      <collision name='FR_link2_collision'>
        <pose>0 0 0 0 -0 0</pose>
        <geometry>
          <mesh>
            <scale>1 1 1</scale>
            <uri>model://magbot_gazebo/description/meshes/R_link2_collision.STL</uri>
          </mesh>
        </geometry>
      </collision>
      <visual name='FR_link2_visual'>
        <pose>0 0 0 0 -0 0</pose>
        <geometry>
          <mesh>
            <scale>1 1 1</scale>
            <uri>model://magbot_gazebo/description/meshes/R_link2.dae</uri>
          </mesh>
        </geometry>
      </visual>
    </link>
    <joint name='FR_theta3' type='revolute'>
      <pose relative_to='FR_link2'>0.13 0 0 0 -0 1.5708</pose>
      <parent>FR_link2</parent>
      <child>FR_link3</child>
      <axis>
        <xyz>0 0 1</xyz>
        <limit>
          <lower>-3</lower>
          <upper>3</upper>
          <effort>10</effort>
          <velocity>3</velocity>
        </limit>
        <dynamics>
          <damping>1000</damping>
          <friction>1000</friction>
          <spring_reference>0</spring_reference>
          <spring_stiffness>0</spring_stiffness>
        </dynamics>
      </axis>
    </joint>
    <link name='FR_link3'>
      <pose relative_to='FR_theta3'>0 0 0 0 -0 0</pose>
      <inertial>
        <pose>0.023023 0 0 0 -0 0</pose>
        <mass>0.12</mass>
        <inertia>
          <ixx>9.96e-06</ixx>
          <ixy>-1.373e-05</ixy>
          <ixz>-3.19e-06</ixz>
          <iyy>0.000516079</iyy>
          <iyz>-2.7e-07</iyz>
          <izz>0.000515499</izz>
        </inertia>
      </inertial>
      <collision name='FR_link3_collision'>
        <pose>0 0 0 0 -0 0</pose>
        <geometry>
          <mesh>
            <scale>1 1 1</scale>
            <uri>model://magbot_gazebo/description/meshes/R_link3_collision.STL</uri>
          </mesh>
        </geometry>
      </collision>
      <collision name='FR_link3_fixed_joint_lump__FR_link4_collision_1'>
        <pose>0.138137 0 0 0 -0 0</pose>
        <geometry>
          <mesh>
            <scale>1 1 1</scale>
            <uri>model://magbot_gazebo/description/meshes/link4_collision.STL</uri>
          </mesh>
        </geometry>
        <surface>
          <contact>
            <ode>
              <kp>1e+06</kp>
              <kd>100</kd>
            </ode>
          </contact>
          <friction>
            <ode>
              <mu>1</mu>
              <mu2>1</mu2>
            </ode>
          </friction>
        </surface>
      </collision>
      <visual name='FR_link3_visual'>
        <pose>0 0 0 0 -0 0</pose>
        <geometry>
          <mesh>
            <scale>1 1 1</scale>
            <uri>model://magbot_gazebo/description/meshes/R_link3.dae</uri>
          </mesh>
        </geometry>
      </visual>
      <visual name='FR_link3_fixed_joint_lump__FR_link4_visual_1'>
        <pose>0.138137 0 0 0 -0 0</pose>
        <geometry>
          <mesh>
            <scale>1 1 1</scale>
            <uri>model://magbot_gazebo/description/meshes/link4.dae</uri>
          </mesh>
        </geometry>
      </visual>
      <min_depth>0.0002</min_depth>
    </link>
    <joint name='RL_theta1' type='revolute'>
      <pose relative_to='base_link'>-0.11165 0.061 -0.0144 1.5708 -0 1.5708</pose>
      <parent>base_link</parent>
      <child>RL_link1</child>
      <axis>
        <xyz>0 0 1</xyz>
        <limit>
          <lower>-0.785398</lower>
          <upper>0.785398</upper>
          <effort>10</effort>
          <velocity>3</velocity>
        </limit>
        <dynamics>
          <damping>1000</damping>
          <friction>1000</friction>
          <spring_reference>0</spring_reference>
          <spring_stiffness>0</spring_stiffness>
        </dynamics>
      </axis>
    </joint>
    <link name='RL_link1'>
      <pose relative_to='RL_theta1'>0 0 0 0 -0 0</pose>
      <inertial>
        <pose>0 0 0 0 -0 0</pose>
        <mass>0.3</mass>
        <inertia>
          <ixx>0.000193</ixx>
          <ixy>0</ixy>
          <ixz>0</ixz>
          <iyy>0.0001489</iyy>
          <iyz>0</iyz>
          <izz>0.0001241</izz>
        </inertia>
      </inertial>
      <collision name='RL_link1_collision'>
        <pose>0 0 0 0 -0 0</pose>
        <geometry>
          <mesh>
            <scale>1 1 1</scale>
            <uri>model://magbot_gazebo/description/meshes/L_link1_collision.STL</uri>
          </mesh>
        </geometry>
      </collision>
      <visual name='RL_link1_visual'>
        <pose>0 0 0 0 -0 0</pose>
        <geometry>
          <mesh>
            <scale>1 1 1</scale>
            <uri>model://magbot_gazebo/description/meshes/RL_link1.dae</uri>
          </mesh>
        </geometry>
      </visual>
    </link>
    <joint name='RL_theta2' type='revolute'>
      <pose relative_to='RL_link1'>0.0496 0.0144 0 1.5708 1.5708 -1.5708</pose>
      <parent>RL_link1</parent>
      <child>RL_link2</child>
      <axis>
        <xyz>0 0 1</xyz>
        <limit>
          <lower>-3</lower>
          <upper>3</upper>
          <effort>10</effort>
          <velocity>3</velocity>
        </limit>
        <dynamics>
          <damping>1000</damping>
          <friction>1000</friction>
          <spring_reference>0</spring_reference>
          <spring_stiffness>0</spring_stiffness>
        </dynamics>
      </axis>
    </joint>
    <link name='RL_link2'>
      <pose relative_to='RL_theta2'>0 0 0 0 -0 0</pose>
      <inertial>
        <pose>0 0 0 0 -0 0</pose>
        <mass>0.1</mass>
        <inertia>
          <ixx>7e-06</ixx>
          <ixy>0</ixy>
          <ixz>4.44e-06</ixz>
          <iyy>0.0001726</iyy>
          <iyz>0</iyz>
          <izz>0.00017568</izz>
        </inertia>
      </inertial>
      <collision name='RL_link2_collision'>
        <pose>0 0 0 0 -0 0</pose>
        <geometry>
          <mesh>
            <scale>1 1 1</scale>
            <uri>model://magbot_gazebo/description/meshes/L_link2_collision.STL</uri>
          </mesh>
        </geometry>
      </collision>
      <visual name='RL_link2_visual'>
        <pose>0 0 0 0 -0 0</pose>
        <geometry>
          <mesh>
            <scale>1 1 1</scale>
            <uri>model://magbot_gazebo/description/meshes/L_link2.dae</uri>
          </mesh>
        </geometry>
      </visual>
    </link>
    <joint name='RL_theta3' type='revolute'>
      <pose relative_to='RL_link2'>0.13 0 0 0 -0 1.5708</pose>
      <parent>RL_link2</parent>
      <child>RL_link3</child>
      <axis>
        <xyz>0 0 1</xyz>
        <limit>
          <lower>-3</lower>
          <upper>3</upper>
          <effort>10</effort>
          <velocity>3</velocity>
        </limit>
        <dynamics>
          <damping>1000</damping>
          <friction>1000</friction>
          <spring_reference>0</spring_reference>
          <spring_stiffness>0</spring_stiffness>
        </dynamics>
      </axis>
    </joint>
    <link name='RL_link3'>
      <pose relative_to='RL_theta3'>0 0 0 0 -0 0</pose>
      <inertial>
        <pose>0.023023 0 0 0 -0 0</pose>
        <mass>0.12</mass>
        <inertia>
          <ixx>9.96e-06</ixx>
          <ixy>-1.373e-05</ixy>
          <ixz>-3.19e-06</ixz>
          <iyy>0.000516079</iyy>
          <iyz>-2.7e-07</iyz>
          <izz>0.000515499</izz>
        </inertia>
      </inertial>
      <collision name='RL_link3_collision'>
        <pose>0 0 0 0 -0 0</pose>
        <geometry>
          <mesh>
            <scale>1 1 1</scale>
            <uri>model://magbot_gazebo/description/meshes/L_link3_collision.STL</uri>
          </mesh>
        </geometry>
      </collision>
      <collision name='RL_link3_fixed_joint_lump__RL_link4_collision_1'>
        <pose>0.138137 0 0 0 -0 0</pose>
        <geometry>
          <mesh>
            <scale>1 1 1</scale>
            <uri>model://magbot_gazebo/description/meshes/link4_collision.STL</uri>
          </mesh>
        </geometry>
        <surface>
          <contact>
            <ode>
              <kp>1e+06</kp>
              <kd>100</kd>
            </ode>
          </contact>
          <friction>
            <ode>
              <mu>1</mu>
              <mu2>1</mu2>
            </ode>
          </friction>
        </surface>
      </collision>
      <visual name='RL_link3_visual'>
        <pose>0 0 0 0 -0 0</pose>
        <geometry>
          <mesh>
            <scale>1 1 1</scale>
            <uri>model://magbot_gazebo/description/meshes/L_link3.dae</uri>
          </mesh>
        </geometry>
      </visual>
      <visual name='RL_link3_fixed_joint_lump__RL_link4_visual_1'>
        <pose>0.138137 0 0 0 -0 0</pose>
        <geometry>
          <mesh>
            <scale>1 1 1</scale>
            <uri>model://magbot_gazebo/description/meshes/link4.dae</uri>
          </mesh>
        </geometry>
      </visual>
      <min_depth>0.0002</min_depth>
    </link>
    <joint name='RR_theta1' type='revolute'>
      <pose relative_to='base_link'>-0.11165 -0.061 -0.0144 1.5708 0 1.5708</pose>
      <parent>base_link</parent>
      <child>RR_link1</child>
      <axis>
        <xyz>0 0 -1</xyz>
        <limit>
          <lower>-0.785398</lower>
          <upper>0.785398</upper>
          <effort>10</effort>
          <velocity>3</velocity>
        </limit>
        <dynamics>
          <damping>1000</damping>
          <friction>1000</friction>
          <spring_reference>0</spring_reference>
          <spring_stiffness>0</spring_stiffness>
        </dynamics>
      </axis>
    </joint>
    <link name='RR_link1'>
      <pose relative_to='RR_theta1'>0 0 0 0 -0 0</pose>
      <inertial>
        <pose>0 0 0 0 -0 0</pose>
        <mass>0.3</mass>
        <inertia>
          <ixx>0.000193</ixx>
          <ixy>0</ixy>
          <ixz>0</ixz>
          <iyy>0.0001489</iyy>
          <iyz>0</iyz>
          <izz>0.0001241</izz>
        </inertia>
      </inertial>
      <collision name='RR_link1_collision'>
        <pose>0 0 0 0 -0 0</pose>
        <geometry>
          <mesh>
            <scale>1 1 1</scale>
            <uri>model://magbot_gazebo/description/meshes/R_link1_collision.STL</uri>
          </mesh>
        </geometry>
      </collision>
      <visual name='RR_link1_visual'>
        <pose>0 0 0 0 -0 0</pose>
        <geometry>
          <mesh>
            <scale>1 1 1</scale>
            <uri>model://magbot_gazebo/description/meshes/RR_link1.dae</uri>
          </mesh>
        </geometry>
      </visual>
    </link>
    <joint name='RR_theta2' type='revolute'>
      <pose relative_to='RR_link1'>-0.0496 0.0144 0 1.5708 1.5708 -1.5708</pose>
      <parent>RR_link1</parent>
      <child>RR_link2</child>
      <axis>
        <xyz>0 0 1</xyz>
        <limit>
          <lower>-3</lower>
          <upper>3</upper>
          <effort>10</effort>
          <velocity>3</velocity>
        </limit>
        <dynamics>
          <damping>1000</damping>
          <friction>1000</friction>
          <spring_reference>0</spring_reference>
          <spring_stiffness>0</spring_stiffness>
        </dynamics>
      </axis>
    </joint>
    <link name='RR_link2'>
      <pose relative_to='RR_theta2'>0 0 0 0 -0 0</pose>
      <inertial>
        <pose>0 0 0 0 -0 0</pose>
        <mass>0.1</mass>
        <inertia>
          <ixx>7e-06</ixx>
          <ixy>0</ixy>
          <ixz>4.44e-06</ixz>
          <iyy>0.0001726</iyy>
          <iyz>0</iyz>
          <izz>0.00017568</izz>
        </inertia>
      </inertial>
      <collision name='RR_link2_collision'>
        <pose>0 0 0 0 -0 0</pose>
        <geometry>
          <mesh>
            <scale>1 1 1</scale>
            <uri>model://magbot_gazebo/description/meshes/R_link2_collision.STL</uri>
          </mesh>
        </geometry>
      </collision>
      <visual name='RR_link2_visual'>
        <pose>0 0 0 0 -0 0</pose>
        <geometry>
          <mesh>
            <scale>1 1 1</scale>
            <uri>model://magbot_gazebo/description/meshes/R_link2.dae</uri>
          </mesh>
        </geometry>
      </visual>
    </link>
    <joint name='RR_theta3' type='revolute'>
      <pose relative_to='RR_link2'>0.13 0 0 0 -0 1.5708</pose>
      <parent>RR_link2</parent>
      <child>RR_link3</child>
      <axis>
        <xyz>0 0 1</xyz>
        <limit>
          <lower>-3</lower>
          <upper>3</upper>
          <effort>10</effort>
          <velocity>3</velocity>
        </limit>
        <dynamics>
          <damping>1000</damping>
          <friction>1000</friction>
          <spring_reference>0</spring_reference>
          <spring_stiffness>0</spring_stiffness>
        </dynamics>
      </axis>
    </joint>
    <link name='RR_link3'>
      <pose relative_to='RR_theta3'>0 0 0 0 -0 0</pose>
      <inertial>
        <pose>0.023023 0 0 0 -0 0</pose>
        <mass>0.12</mass>
        <inertia>
          <ixx>9.96e-06</ixx>
          <ixy>-1.373e-05</ixy>
          <ixz>-3.19e-06</ixz>
          <iyy>0.000516079</iyy>
          <iyz>-2.7e-07</iyz>
          <izz>0.000515499</izz>
        </inertia>
      </inertial>
      <collision name='RR_link3_collision'>
        <pose>0 0 0 0 -0 0</pose>
        <geometry>
          <mesh>
            <scale>1 1 1</scale>
            <uri>model://magbot_gazebo/description/meshes/R_link3_collision.STL</uri>
          </mesh>
        </geometry>
      </collision>
      <collision name='RR_link3_fixed_joint_lump__RR_link4_collision_1'>
        <pose>0.138137 0 0 0 -0 0</pose>
        <geometry>
          <mesh>
            <scale>1 1 1</scale>
            <uri>model://magbot_gazebo/description/meshes/link4_collision.STL</uri>
          </mesh>
        </geometry>
        <surface>
          <contact>
            <ode>
              <kp>1e+06</kp>
              <kd>100</kd>
            </ode>
          </contact>
          <friction>
            <ode>
              <mu>1</mu>
              <mu2>1</mu2>
            </ode>
          </friction>
        </surface>
      </collision>
      <visual name='RR_link3_visual'>
        <pose>0 0 0 0 -0 0</pose>
        <geometry>
          <mesh>
            <scale>1 1 1</scale>
            <uri>model://magbot_gazebo/description/meshes/R_link3.dae</uri>
          </mesh>
        </geometry>
      </visual>
      <visual name='RR_link3_fixed_joint_lump__RR_link4_visual_1'>
        <pose>0.138137 0 0 0 -0 0</pose>
        <geometry>
          <mesh>
            <scale>1 1 1</scale>
            <uri>model://magbot_gazebo/description/meshes/link4.dae</uri>
          </mesh>
        </geometry>
      </visual>
      <min_depth>0.0002</min_depth>
    </link>
    <plugin name='gazebo_ros2_control' filename='libgazebo_ros2_control.so'>
      <parameters>/home/jarvis/magic/ROS/magbot_ws/install/magbot_gazebo/share/magbot_gazebo/config/dingo_controllers.yaml</parameters>
    </plugin>
    <static>0</static>
    <plugin name='joint_state_publisher' filename='libgazebo_ros_joint_state_publisher.so'>
      <ros>
        <namespace>/dingo_gazebo</namespace>
        <remapping>~/out:=joint_states</remapping>
      </ros>
      <update_rate>50</update_rate>
      <joint_name>FR_theta1</joint_name>
      <joint_name>FR_theta2</joint_name>
      <joint_name>FR_theta3</joint_name>
      <joint_name>FL_theta1</joint_name>
      <joint_name>FL_theta2</joint_name>
      <joint_name>FL_theta3</joint_name>
      <joint_name>RR_theta1</joint_name>
      <joint_name>RR_theta2</joint_name>
      <joint_name>RR_theta3</joint_name>
      <joint_name>RL_theta1</joint_name>
      <joint_name>RL_theta2</joint_name>
      <joint_name>RL_theta3</joint_name>
    </plugin>
  </model>
</sdf>
